Workbook

Sheet Instructions

Sheet 3RD TERM Report Card
L5: Insert School Logo
D6: TYPE THE NAME OF YOUR SCHOOL HERE!
D7: STUDENT REPORT CARD | F7: Age: | G7: =VLOOKUP(B8,'1ST TERM Db'!A4:CI503,87,0) -> 14 yrs | H7: Class Category: | J7: ='1ST TERM Db'!CL4 -> Arts
B8: 1 | C8: Student Name: | D8: =VLOOKUP(B8,'3RD TERM Db'!A4:B503,2,0) -> ADEBAYO JAMAL | G8: Gender | H8: =VLOOKUP(B8,'3RD TERM Db'!A4:E503,4,0) -> MALE | I8: Adm. No. | J8: =VLOOKUP(B8,'3RD TERM Db'!A4:C503,3,0) -> 2806 | K8: Class: | L8: =VLOOKUP(B8,'3RD TERM Db'!A4:E503,5,0) -> SSS3C
B9: Number of Subjects Offered: | D9: =COUNTIF(D14:D30,"=100") -> 11 | E9: Number Passed: | F9: =COUNTIF(J14:J30,">=40") -> 10 | G9: Number Failed: | H9: =D9-F9 -> 1 | I9: Number of Students in Class: | J9: =VLOOKUP(B8,'3RD TERM Db'!A4:F503,6,0) -> 40 | K9: Class Position | L9: =VLOOKUP(B8,'3RD TERM Db'!A4:DO503,119,0) -> 1
B10: No of Times School Opened: | D10: =VLOOKUP(B8,'3RD TERM Db'!A4:G503,7,0) -> 224 | E10: No of Times Present: | F10: =VLOOKUP(B8,'3RD TERM Db'!A4:H503,8,0) -> 212 | G10: No of Times Absent: | H10: =VLOOKUP(B8,'3RD TERM Db'!A4:I503,9,0) -> 12 | I10: Academic Session: | J10: =VLOOKUP(B8,'3RD TERM Db'!A4:DX503,128,0) -> 2025/2026 | K10: Term: | L10: =VLOOKUP(B8,'3RD TERM Db'!A4:DY503,129,0) -> THIRD
B11: COGNITIVE (ACADEMIC PERFORMANCE)
B12: S/NO | C12: Subject | D12: Marks Obtainable | E12: 3rd Term C.A. | F12: 3rd Term Exam | G12: Total Mark | K12: Grade Obtained | L12: Remarks
E13: 0.3 | F13: 0.7 | G13: 3rd Term Total (100%) | H13: 2nd Term Total (100%) | I13: 1st Term Total (100%) | J13: Average Score in %
B14: 1 | C14: ='3RD TERM Db'!K2 -> General Mathematics | D14: =IF(AND(G14=0,H14=0,I14=0),"--",100) -> 100 | E14: =VLOOKUP(B8,'3RD TERM Db'!A4:J503,10,0) -> 23 | F14: =VLOOKUP(B8,'3RD TERM Db'!A4:K503,11,0) -> 69 | G14: =VLOOKUP(B8,'3RD TERM Db'!A4:L503,12,0) -> 92 | H14: =VLOOKUP(B8,'3RD TERM Db'!A4:M503,13,0) -> 92 | I14: =VLOOKUP(B8,'3RD TERM Db'!A4:N503,14,0) -> 0 | J14: =VLOOKUP(B8,'3RD TERM Db'!A4:O503,15,0) -> 92 | K14: =IF(J14>=70,"A",IF(J14>=50,"C",IF(J14>=40,"P",IF(J14>=1,"F","NA")))) -> A | L14: =IF(K14="A","DISTINCTION",IF(K14="C","GOOD",IF(K14="P","PASS",IF(K14="F","FAIL",IF(K14="NA","NOT APPLICABLE",""))))) -> DISTINCTION
B15: 2 | C15: ='3RD TERM Db'!Q2 -> English Language | D15: =IF(AND(G15=0,H15=0,I15=0),"--",100) -> 100 | E15: =VLOOKUP(B8,'3RD TERM Db'!A4:P503,16,0) -> 16 | F15: =VLOOKUP(B8,'3RD TERM Db'!A4:Q503,17,0) -> 56 | G15: =VLOOKUP(B8,'3RD TERM Db'!A4:R503,18,0) -> 72 | H15: =VLOOKUP(B8,'3RD TERM Db'!A4:S503,19,0) -> 93 | I15: =VLOOKUP(B8,'3RD TERM Db'!A4:T503,20,0) -> 0 | J15: =VLOOKUP(B8,'3RD TERM Db'!A4:U503,21,0) -> 82.5 | K15: =IF(J15>=70,"A",IF(J15>=50,"C",IF(J15>=40,"P",IF(J15>=1,"F","NA")))) -> A | L15: =IF(K15="A","DISTINCTION",IF(K15="C","GOOD",IF(K15="P","PASS",IF(K15="F","FAIL",IF(K15="NA","NOT APPLICABLE",""))))) -> DISTINCTION
B16: 3 | C16: ='3RD TERM Db'!W2 -> Civic Education | D16: =IF(AND(G16=0,H16=0,I16=0),"--",100) -> 100 | E16: =VLOOKUP(B8,'3RD TERM Db'!A4:V503,22,0) -> 23 | F16: =VLOOKUP(B8,'3RD TERM Db'!A4:W503,23,0) -> 70 | G16: =VLOOKUP(B8,'3RD TERM Db'!A4:X503,24,0) -> 93 | H16: =VLOOKUP(B8,'3RD TERM Db'!A4:Y503,25,0) -> 100 | I16: =VLOOKUP(B8,'3RD TERM Db'!A4:Z503,26,0) -> 0 | J16: =VLOOKUP(B8,'3RD TERM Db'!A4:AA503,27,0) -> 96.5 | K16: =IF(J16>=70,"A",IF(J16>=50,"C",IF(J16>=40,"P",IF(J16>=1,"F","NA")))) -> A | L16: =IF(K16="A","DISTINCTION",IF(K16="C","GOOD",IF(K16="P","PASS",IF(K16="F","FAIL",IF(K16="NA","NOT APPLICABLE",""))))) -> DISTINCTION
B17: 4 | C17: ='3RD TERM Db'!AC2 -> Chemistry | D17: =IF(AND(G17=0,H17=0,I17=0),"--",100) -> 100 | E17: =VLOOKUP(B8,'3RD TERM Db'!A4:AB503,28,0) -> 27 | F17: =VLOOKUP(B8,'3RD TERM Db'!A4:AC503,29,0) -> 62 | G17: =VLOOKUP(B8,'3RD TERM Db'!A4:AD503,30,0) -> 89 | H17: =VLOOKUP(B8,'3RD TERM Db'!A4:AE503,31,0) -> 95 | I17: =VLOOKUP(B8,'3RD TERM Db'!A4:AF503,32,0) -> 0 | J17: =VLOOKUP(B8,'3RD TERM Db'!A4:AG503,33,0) -> 92 | K17: =IF(J17>=70,"A",IF(J17>=50,"C",IF(J17>=40,"P",IF(J17>=1,"F","NA")))) -> A | L17: =IF(K17="A","DISTINCTION",IF(K17="C","GOOD",IF(K17="P","PASS",IF(K17="F","FAIL",IF(K17="NA","NOT APPLICABLE",""))))) -> DISTINCTION
B18: 5 | C18: ='3RD TERM Db'!AI2 -> Biology | D18: =IF(AND(G18=0,H18=0,I18=0),"--",100) -> 100 | E18: =VLOOKUP(B8,'3RD TERM Db'!A4:AH503,34,0) -> 20 | F18: =VLOOKUP(B8,'3RD TERM Db'!A4:AI503,35,0) -> 46 | G18: =VLOOKUP(B8,'3RD TERM Db'!A4:AJ503,36,0) -> 66 | H18: =VLOOKUP(B8,'3RD TERM Db'!A4:AK503,37,0) -> 75 | I18: =VLOOKUP(B8,'3RD TERM Db'!A4:AL503,38,0) -> 0 | J18: =VLOOKUP(B8,'3RD TERM Db'!A4:AM503,39,0) -> 70.5 | K18: =IF(J18>=70,"A",IF(J18>=50,"C",IF(J18>=40,"P",IF(J18>=1,"F","NA")))) -> A | L18: =IF(K18="A","DISTINCTION",IF(K18="C","GOOD",IF(K18="P","PASS",IF(K18="F","FAIL",IF(K18="NA","NOT APPLICABLE",""))))) -> DISTINCTION
B19: 6 | C19: ='3RD TERM Db'!AO2 -> Physics | D19: =IF(AND(G19=0,H19=0,I19=0),"--",100) -> 100 | E19: =VLOOKUP(B8,'3RD TERM Db'!A4:AN503,40,0) -> 0 | F19: =VLOOKUP(B8,'3RD TERM Db'!A4:AO503,41,0) -> 0 | G19: =VLOOKUP(B8,'3RD TERM Db'!A4:AP503,42,0) -> 0 | H19: =VLOOKUP(B8,'3RD TERM Db'!A4:AQ503,43,0) -> 84 | I19: =VLOOKUP(B8,'3RD TERM Db'!A4:AR503,44,0) -> 0 | J19: =VLOOKUP(B8,'3RD TERM Db'!A4:AS503,45,0) -> 84 | K19: =IF(J19>=70,"A",IF(J19>=50,"C",IF(J19>=40,"P",IF(J19>=1,"F","NA")))) -> A | L19: =IF(K19="A","DISTINCTION",IF(K19="C","GOOD",IF(K19="P","PASS",IF(K19="F","FAIL",IF(K19="NA","NOT APPLICABLE",""))))) -> DISTINCTION
B20: 7 | C20: ='3RD TERM Db'!AU2 -> Financial Accounting | D20: =IF(AND(G20=0,H20=0,I20=0),"--",100) -> 100 | E20: =VLOOKUP(B8,'3RD TERM Db'!A4:AT503,46,0) -> 12 | F20: =VLOOKUP(B8,'3RD TERM Db'!A4:AU503,47,0) -> 34 | G20: =VLOOKUP(B8,'3RD TERM Db'!A4:AV503,48,0) -> 46 | H20: =VLOOKUP(B8,'3RD TERM Db'!A4:AW503,49,0) -> 74 | I20: =VLOOKUP(B8,'3RD TERM Db'!A4:AX503,50,0) -> 0 | J20: =VLOOKUP(B8,'3RD TERM Db'!A4:AY503,51,0) -> 60 | K20: =IF(J20>=70,"A",IF(J20>=50,"C",IF(J20>=40,"P",IF(J20>=1,"F","NA")))) -> C | L20: =IF(K20="A","DISTINCTION",IF(K20="C","GOOD",IF(K20="P","PASS",IF(K20="F","FAIL",IF(K20="NA","NOT APPLICABLE",""))))) -> GOOD
B21: 8 | C21: ='3RD TERM Db'!BA2 -> Commerce | D21: =IF(AND(G21=0,H21=0,I21=0),"--",100) -> 100 | E21: =VLOOKUP(B8,'3RD TERM Db'!A4:AZ503,52,0) -> 20 | F21: =VLOOKUP(B8,'3RD TERM Db'!A4:BA503,53,0) -> 34 | G21: =VLOOKUP(B8,'3RD TERM Db'!A4:BB503,54,0) -> 54 | H21: =VLOOKUP(B8,'3RD TERM Db'!A4:BC503,55,0) -> 89 | I21: =VLOOKUP(B8,'3RD TERM Db'!A4:BD503,56,0) -> 0 | J21: =VLOOKUP(B8,'3RD TERM Db'!A4:BE503,57,0) -> 71.5 | K21: =IF(J21>=70,"A",IF(J21>=50,"C",IF(J21>=40,"P",IF(J21>=1,"F","NA")))) -> A | L21: =IF(K21="A","DISTINCTION",IF(K21="C","GOOD",IF(K21="P","PASS",IF(K21="F","FAIL",IF(K21="NA","NOT APPLICABLE",""))))) -> DISTINCTION
B22: 9 | C22: ='3RD TERM Db'!BG2 -> Economics | D22: =IF(AND(G22=0,H22=0,I22=0),"--",100) -> 100 | E22: =VLOOKUP(B8,'3RD TERM Db'!A4:BF503,58,0) -> 11 | F22: =VLOOKUP(B8,'3RD TERM Db'!A4:BG503,59,0) -> 23 | G22: =VLOOKUP(B8,'3RD TERM Db'!A4:BH503,60,0) -> 34 | H22: =VLOOKUP(B8,'3RD TERM Db'!A4:BI503,61,0) -> 35 | I22: =VLOOKUP(B8,'3RD TERM Db'!A4:BJ503,62,0) -> 43 | J22: =VLOOKUP(B8,'3RD TERM Db'!A4:BK503,63,0) -> 37.3 | K22: =IF(J22>=70,"A",IF(J22>=50,"C",IF(J22>=40,"P",IF(J22>=1,"F","NA")))) -> F | L22: =IF(K22="A","DISTINCTION",IF(K22="C","GOOD",IF(K22="P","PASS",IF(K22="F","FAIL",IF(K22="NA","NOT APPLICABLE",""))))) -> FAIL
B23: 10 | C23: ='3RD TERM Db'!BM2 -> Government | D23: =IF(AND(G23=0,H23=0,I23=0),"--",100) -> 100 | E23: =VLOOKUP(B8,'3RD TERM Db'!A4:BL503,64,0) -> 23 | F23: =VLOOKUP(B8,'3RD TERM Db'!A4:BM503,65,0) -> 60 | G23: =VLOOKUP(B8,'3RD TERM Db'!A4:BN503,66,0) -> 83 | H23: =VLOOKUP(B8,'3RD TERM Db'!A4:BO503,67,0) -> 90 | I23: =VLOOKUP(B8,'3RD TERM Db'!A4:BP503,68,0) -> 0 | J23: =VLOOKUP(B8,'3RD TERM Db'!A4:BQ503,69,0) -> 86.5 | K23: =IF(J23>=70,"A",IF(J23>=50,"C",IF(J23>=40,"P",IF(J23>=1,"F","NA")))) -> A | L23: =IF(K23="A","DISTINCTION",IF(K23="C","GOOD",IF(K23="P","PASS",IF(K23="F","FAIL",IF(K23="NA","NOT APPLICABLE",""))))) -> DISTINCTION
B24: 11 | C24: ='3RD TERM Db'!BS2 -> Literature in English | D24: =IF(AND(G24=0,H24=0,I24=0),"--",100) -> 100 | E24: =VLOOKUP(B8,'3RD TERM Db'!A4:BR503,70,0) -> 12 | F24: =VLOOKUP(B8,'3RD TERM Db'!A4:BS503,71,0) -> 23 | G24: =VLOOKUP(B8,'3RD TERM Db'!A4:BT503,72,0) -> 35 | H24: =VLOOKUP(B8,'3RD TERM Db'!A4:BU503,73,0) -> 47 | I24: =VLOOKUP(B8,'3RD TERM Db'!A4:BV503,74,0) -> 0 | J24: =VLOOKUP(B8,'3RD TERM Db'!A4:BW503,75,0) -> 41 | K24: =IF(J24>=70,"A",IF(J24>=50,"C",IF(J24>=40,"P",IF(J24>=1,"F","NA")))) -> P | L24: =IF(K24="A","DISTINCTION",IF(K24="C","GOOD",IF(K24="P","PASS",IF(K24="F","FAIL",IF(K24="NA","NOT APPLICABLE",""))))) -> PASS
B25: 12 | C25: ='3RD TERM Db'!BY2 -> CRS | D25: =IF(AND(G25=0,H25=0,I25=0),"--",100) -> -- | E25: =VLOOKUP(B8,'3RD TERM Db'!A4:BX503,76,0) -> 0 | F25: =VLOOKUP(B8,'3RD TERM Db'!A4:BY503,77,0) -> 0 | G25: =VLOOKUP(B8,'3RD TERM Db'!A4:BZ503,78,0) -> 0 | H25: =VLOOKUP(B8,'3RD TERM Db'!A4:CA503,79,0) -> 0 | I25: =VLOOKUP(B8,'3RD TERM Db'!A4:CB503,80,0) -> 0 | J25: =VLOOKUP(B8,'3RD TERM Db'!A4:CC503,81,0) -> 0 | K25: =IF(J25>=70,"A",IF(J25>=50,"C",IF(J25>=40,"P",IF(J25>=1,"F","NA")))) -> NA | L25: =IF(K25="A","DISTINCTION",IF(K25="C","GOOD",IF(K25="P","PASS",IF(K25="F","FAIL",IF(K25="NA","NOT APPLICABLE",""))))) -> NOT APPLICABLE
B26: 13 | C26: ='3RD TERM Db'!CE2 -> IRS | D26: =IF(AND(G26=0,H26=0,I26=0),"--",100) -> -- | E26: =VLOOKUP(B8,'3RD TERM Db'!A4:CD503,82,0) -> 0 | F26: =VLOOKUP(B8,'3RD TERM Db'!A4:CE503,83,0) -> 0 | G26: =VLOOKUP(B8,'3RD TERM Db'!A4:CF503,84,0) -> 0 | H26: =VLOOKUP(B8,'3RD TERM Db'!A4:CG503,85,0) -> 0 | I26: =VLOOKUP(B8,'3RD TERM Db'!A4:CH503,86,0) -> 0 | J26: =VLOOKUP(B8,'3RD TERM Db'!A4:CI503,87,0) -> 0 | K26: =IF(J26>=70,"A",IF(J26>=50,"C",IF(J26>=40,"P",IF(J26>=1,"F","NA")))) -> NA | L26: =IF(K26="A","DISTINCTION",IF(K26="C","GOOD",IF(K26="P","PASS",IF(K26="F","FAIL",IF(K26="NA","NOT APPLICABLE",""))))) -> NOT APPLICABLE
B27: 14 | C27: ='3RD TERM Db'!CK2 -> Geography | D27: =IF(AND(G27=0,H27=0,I27=0),"--",100) -> -- | E27: =VLOOKUP(B8,'3RD TERM Db'!A4:CJ503,88,0) -> 0 | F27: =VLOOKUP(B8,'3RD TERM Db'!A4:CK503,89,0) -> 0 | G27: =VLOOKUP(B8,'3RD TERM Db'!A4:CL503,90,0) -> 0 | H27: =VLOOKUP(B8,'3RD TERM Db'!A4:CM503,91,0) -> 0 | I27: =VLOOKUP(B8,'3RD TERM Db'!A4:CN503,92,0) -> 0 | J27: =VLOOKUP(B8,'3RD TERM Db'!A4:CO503,93,0) -> 0 | K27: =IF(J27>=70,"A",IF(J27>=50,"C",IF(J27>=40,"P",IF(J27>=1,"F","NA")))) -> NA | L27: =IF(K27="A","DISTINCTION",IF(K27="C","GOOD",IF(K27="P","PASS",IF(K27="F","FAIL",IF(K27="NA","NOT APPLICABLE",""))))) -> NOT APPLICABLE
B28: 15 | C28: ='3RD TERM Db'!CQ2 -> Further Mathematics | D28: =IF(AND(G28=0,H28=0,I28=0),"--",100) -> -- | E28: =VLOOKUP(B8,'3RD TERM Db'!A4:CP503,94,0) -> 0 | F28: =VLOOKUP(B8,'3RD TERM Db'!A4:CQ503,95,0) -> 0 | G28: =VLOOKUP(B8,'3RD TERM Db'!A4:CR503,96,0) -> 0 | H28: =VLOOKUP(B8,'3RD TERM Db'!A4:CS503,97,0) -> 0 | I28: =VLOOKUP(B8,'3RD TERM Db'!A4:CT503,98,0) -> 0 | J28: =VLOOKUP(B8,'3RD TERM Db'!A4:CU503,99,0) -> 0 | K28: =IF(J28>=70,"A",IF(J28>=50,"C",IF(J28>=40,"P",IF(J28>=1,"F","NA")))) -> NA | L28: =IF(K28="A","DISTINCTION",IF(K28="C","GOOD",IF(K28="P","PASS",IF(K28="F","FAIL",IF(K28="NA","NOT APPLICABLE",""))))) -> NOT APPLICABLE
B29: 16 | C29: ='3RD TERM Db'!CW2 -> Agricultural Science | D29: =IF(AND(G29=0,H29=0,I29=0),"--",100) -> -- | E29: =VLOOKUP(B8,'3RD TERM Db'!A4:CV503,100,0) -> 0 | F29: =VLOOKUP(B8,'3RD TERM Db'!A4:CW503,101,0) -> 0 | G29: =VLOOKUP(B8,'3RD TERM Db'!A4:CX503,102,0) -> 0 | H29: =VLOOKUP(B8,'3RD TERM Db'!A4:CY503,103,0) -> 0 | I29: =VLOOKUP(B8,'3RD TERM Db'!A4:CZ503,104,0) -> 0 | J29: =VLOOKUP(B8,'3RD TERM Db'!A4:DA503,105,0) -> 0 | K29: =IF(J29>=70,"A",IF(J29>=50,"C",IF(J29>=40,"P",IF(J29>=1,"F","NA")))) -> NA | L29: =IF(K29="A","DISTINCTION",IF(K29="C","GOOD",IF(K29="P","PASS",IF(K29="F","FAIL",IF(K29="NA","NOT APPLICABLE",""))))) -> NOT APPLICABLE
B30: 17 | C30: ='3RD TERM Db'!DC2 -> Yoruba | D30: =IF(AND(G30=0,H30=0,I30=0),"--",100) -> -- | E30: =VLOOKUP(B8,'3RD TERM Db'!A4:DB503,106,0) -> 0 | F30: =VLOOKUP(B8,'3RD TERM Db'!A4:DC503,107,0) -> 0 | G30: =VLOOKUP(B8,'3RD TERM Db'!A4:DD503,108,0) -> 0 | H30: =VLOOKUP(B8,'3RD TERM Db'!A4:DE503,109,0) -> 0 | I30: =VLOOKUP(B8,'3RD TERM Db'!A4:DF503,110,0) -> 0 | J30: =VLOOKUP(B8,'3RD TERM Db'!A4:DG503,111,0) -> 0 | K30: =IF(J30>=70,"A",IF(J30>=50,"C",IF(J30>=40,"P",IF(J30>=1,"F","NA")))) -> NA | L30: =IF(K30="A","DISTINCTION",IF(K30="C","GOOD",IF(K30="P","PASS",IF(K30="F","FAIL",IF(K30="NA","NOT APPLICABLE",""))))) -> NOT APPLICABLE
B31: 18 | C31: ='3RD TERM Db'!DI2 -> Data Processing | D31: =IF(AND(G31=0,H31=0,I31=0),"--",100) -> -- | E31: =VLOOKUP(B8,'3RD TERM Db'!A4:DH503,112,0) -> 0 | F31: =VLOOKUP(B8,'3RD TERM Db'!A4:DI503,113,0) -> 0 | G31: =VLOOKUP(B8,'3RD TERM Db'!A4:DJ503,114,0) -> 0 | H31: =VLOOKUP(B8,'3RD TERM Db'!A4:DK503,115,0) -> 0 | I31: =VLOOKUP(B8,'3RD TERM Db'!A4:DL503,116,0) -> 0 | J31: =VLOOKUP(B8,'3RD TERM Db'!A4:DM503,117,0) -> 0 | K31: =IF(J31>=70,"A",IF(J31>=50,"C",IF(J31>=40,"P",IF(J31>=1,"F","NA")))) -> NA | L31: =IF(K31="A","DISTINCTION",IF(K31="C","GOOD",IF(K31="P","PASS",IF(K31="F","FAIL",IF(K31="NA","NOT APPLICABLE",""))))) -> NOT APPLICABLE
B32: TOTAL MARKS OBTAINABLE: | D32: =SUM(D14:D31) -> 1100 | H32: TOTAL MARKS OBTAINED: | J32: =SUM(J14:J30) -> 813.8 | K32: % | L32: =FLOOR(J32/D32*100,0.1) -> 73.9
B33: GRADE INTERPRETATION ::: A: DISTINCTION C: CREDIT P: PASS F: FAIL
B34: BEHAVIOURAL (AFFECTIVE DOMAIN)
B35: PUNCTUALITY | D35: NEATNESS | E35: ATTENTIVENESS | F35: RELATIONSHIP WITH OTHERS | G35: POLITENESS | H35: RESPONSIVENESS | I35: COMMITMENT | J35: CONSISTENCY | K35: TOTAL SCORE | L35: 40
B36: =VLOOKUP(B8,'3RD TERM Db'!A4:DP503,120,0) -> EXCELLENT(5) | D36: =VLOOKUP(B8,'3RD TERM Db'!A4:DQ503,121,0) -> EXCELLENT(5) | E36: =VLOOKUP(B8,'3RD TERM Db'!A4:DR503,122,0) -> GOOD(4) | F36: =VLOOKUP(B8,'3RD TERM Db'!A4:DS503,123,0) -> AVERAGE(3) | G36: =VLOOKUP(B8,'3RD TERM Db'!A4:DT503,124,0) -> GOOD(4) | H36: =VLOOKUP(B8,'3RD TERM Db'!A4:DU503,125,0) -> GOOD(4) | I36: =VLOOKUP(B8,'3RD TERM Db'!A4:DV503,126,0) -> GOOD(4) | J36: =VLOOKUP(B8,'3RD TERM Db'!A4:DW503,127,0) -> EXCELLENT(5) | K36: SCORE OBTAINED | L36: =SUM(B37:J37) -> 34
B37: =IF(B36="EXCELLENT(5)",5,IF(B36="GOOD(4)",4,IF(B36="AVERAGE(3)",3,IF(B36="BELOW AVERAGE(2)",2,IF(B36="FAIR(1)",1,"--"))))) -> 5 | D37: =IF(D36="EXCELLENT(5)",5,IF(D36="GOOD(4)",4,IF(D36="AVERAGE(3)",3,IF(D36="BELOW AVERAGE(2)",2,IF(D36="FAIR(1)",1,"--"))))) -> 5 | E37: =IF(E36="EXCELLENT(5)",5,IF(E36="GOOD(4)",4,IF(E36="AVERAGE(3)",3,IF(E36="BELOW AVERAGE(2)",2,IF(E36="FAIR(1)",1,"--"))))) -> 4 | F37: =IF(F36="EXCELLENT(5)",5,IF(F36="GOOD(4)",4,IF(F36="AVERAGE(3)",3,IF(F36="BELOW AVERAGE(2)",2,IF(F36="FAIR(1)",1,"--"))))) -> 3 | G37: =IF(G36="EXCELLENT(5)",5,IF(G36="GOOD(4)",4,IF(G36="AVERAGE(3)",3,IF(G36="BELOW AVERAGE(2)",2,IF(G36="FAIR(1)",1,"--"))))) -> 4 | H37: =IF(H36="EXCELLENT(5)",5,IF(H36="GOOD(4)",4,IF(H36="AVERAGE(3)",3,IF(H36="BELOW AVERAGE(2)",2,IF(H36="FAIR(1)",1,"--"))))) -> 4 | I37: =IF(I36="EXCELLENT(5)",5,IF(I36="GOOD(4)",4,IF(I36="AVERAGE(3)",3,IF(I36="BELOW AVERAGE(2)",2,IF(I36="FAIR(1)",1,"--"))))) -> 4 | J37: =IF(J36="EXCELLENT(5)",5,IF(J36="GOOD(4)",4,IF(J36="AVERAGE(3)",3,IF(J36="BELOW AVERAGE(2)",2,IF(J36="FAIR(1)",1,"--"))))) -> 5
B38: PSYCHOMOTOR DOMAIN
B39: CRAFTS/DRAWING & PAINTING | D39: TECHNICAL SKILLS | E39: ICT SKILLS | F39: GARDENING/ FARMING SKILLS | G39: GAMES & SPORTS | H39: CREATIVITY & INITIATIVE | J39: VERBAL FLUENCY | K39: TOTAL SCORE | L39: =SUM(C50:I50) -> 25
B40: =VLOOKUP(B8,'3RD TERM Db'!A4:DZ503,130,0) -> GOOD(4) | D40: =VLOOKUP(B8,'3RD TERM Db'!A4:EA503,131,0) -> OPTIONAL | E40: =VLOOKUP(B8,'3RD TERM Db'!A4:EB503,132,0) -> OPTIONAL | F40: =VLOOKUP(B8,'3RD TERM Db'!A4:EC503,133,0) -> GOOD(4) | G40: =VLOOKUP(B8,'3RD TERM Db'!A4:ED503,134,0) -> GOOD(4) | H40: =VLOOKUP(B8,'3RD TERM Db'!A4:EE503,135,0) -> AVERAGE(3) | J40: =VLOOKUP(B8,'3RD TERM Db'!A4:EF503,136,0) -> GOOD(4) | K40: SCORE OBTAINED | L40: =SUM(B41:K41) -> 19
B41: =IF(B40="EXCELLENT(5)",5,IF(B40="GOOD(4)",4,IF(B40="AVERAGE(3)",3,IF(B40="BELOW AVERAGE(2)",2,IF(B40="FAIR(1)",1,"--"))))) -> 4 | D41: =IF(D40="EXCELLENT(5)",5,IF(D40="GOOD(4)",4,IF(D40="AVERAGE(3)",3,IF(D40="BELOW AVERAGE(2)",2,IF(D40="FAIR(1)",1,"--"))))) -> -- | E41: =IF(E40="EXCELLENT(5)",5,IF(E40="GOOD(4)",4,IF(E40="AVERAGE(3)",3,IF(E40="BELOW AVERAGE(2)",2,IF(E40="FAIR(1)",1,"--"))))) -> -- | F41: =IF(F40="EXCELLENT(5)",5,IF(F40="GOOD(4)",4,IF(F40="AVERAGE(3)",3,IF(F40="BELOW AVERAGE(2)",2,IF(F40="FAIR(1)",1,"--"))))) -> 4 | G41: =IF(G40="EXCELLENT(5)",5,IF(G40="GOOD(4)",4,IF(G40="AVERAGE(3)",3,IF(G40="BELOW AVERAGE(2)",2,IF(G40="FAIR(1)",1,"--"))))) -> 4 | H41: =IF(H40="EXCELLENT(5)",5,IF(H40="GOOD(4)",4,IF(H40="AVERAGE(3)",3,IF(H40="BELOW AVERAGE(2)",2,IF(H40="FAIR(1)",1,"--"))))) -> 3 | J41: =IF(J40="EXCELLENT(5)",5,IF(J40="GOOD(4)",4,IF(J40="AVERAGE(3)",3,IF(J40="BELOW AVERAGE(2)",2,IF(J40="FAIR(1)",1,"--"))))) -> 4
B42: NON-COGNITIVE ASPECTS RATING KEYS: 5-Excellent 4-Good 3-Average 2-Below Average 1-Fair
B43: Class Tutor's Comment: | D43: =VLOOKUP(B8,'3RD TERM Db'!A4:EG503,137,0) -> Add the Tutor's Comment . . . | H43: Class Tutor's Name: | I43: =VLOOKUP(B8,'3RD TERM Db'!A4:EI503,139,0) -> Mr. Akinwale Ibrahim
B44: Principal´s Comment: | D44: =VLOOKUP(B8,'3RD TERM Db'!A4:EH503,138,0) -> Choose Principals comment | J44: Parent Signature:
...

Sheet 3RD TERM Db
A1: 1 | B1: 2 | C1: 3 | D1: 4 | E1: 5 | F1: 6 | G1: 7 | H1: 8 | I1: 9 | J1: 10 | K1: 11 | L1: 12 | M1: 13 | N1: 14 | O1: 15 | P1: 16 | Q1: 17 | R1: 18 | S1: 19 | T1: 20 | U1: 21 | V1: 22 | W1: 23 | X1: 24 | Y1: 25 | Z1: 26 | AA1: 27 | AB1: 28 | AC1: 29 | AD1: 30 | AE1: 31 | AF1: 32 | AG1: 33 | AH1: 34 | AI1: 35 | AJ1: 36 | AK1: 37 | AL1: 38 | AM1: 39 | AN1: 40 | AO1: 41 | AP1: 42 | AQ1: 43 | AR1: 44 | AS1: 45 | AT1: 46 | AU1: 47 | AV1: 48 | AW1: 49 | AX1: 50 | AY1: 51 | AZ1: 52 | BA1: 53 | BB1: 54 | BC1: 55 | BD1: 56 | BE1: 57 | BF1: 58 | BG1: 59 | BH1: 60 | BI1: 61 | BJ1: 62 | BK1: 63 | BL1: 64 | BM1: 65 | BN1: 66 | BO1: 67 | BP1: 68 | BQ1: 69 | BR1: 70 | BS1: 71 | BT1: 72 | BU1: 73 | BV1: 74 | BW1: 75 | BX1: 76 | BY1: 77 | BZ1: 78 | CA1: 79 | CB1: 80 | CC1: 81 | CD1: 82 | CE1: 83 | CF1: 84 | CG1: 85 | CH1: 86 | CI1: 87 | CJ1: 88 | CK1: 89 | CL1: 90 | CM1: 91 | CN1: 92 | CO1: 93 | CP1: 94 | CQ1: 95 | CR1: 96 | CS1: 97 | CT1: 98 | CU1: 99 | CV1: 100 | CW1: 101 | CX1: 102 | CY1: 103 | CZ1: 104 | DA1: 105 | DB1: 106 | DC1: 107 | DD1: 108 | DE1: 109 | DF1: 110 | DG1: 111 | DH1: 112 | DI1: 113 | DJ1: 114 | DK1: 115 | DL1: 116 | DM1: 117 | DN1: 118 | DO1: 119 | DP1: 120 | DQ1: 121 | DR1: 122 | DS1: 123 | DT1: 124 | DU1: 125 | DV1: 126 | DW1: 127 | DX1: 128 | DY1: 129 | DZ1: 130 | EA1: 131 | EB1: 132 | EC1: 133 | ED1: 134 | EE1: 135 | EF1: 136 | EG1: 137 | EH1: 138 | EI1: 139 | EJ1: 140
J2: 1 | K2: ='1ST TERM Db'!K2:L2 -> General Mathematics | P2: 2 | Q2: ='1ST TERM Db'!N2 -> English Language | V2: 3 | W2: ='1ST TERM Db'!Q2 -> Civic Education | AB2: 4 | AC2: ='1ST TERM Db'!T2 -> Chemistry | AH2: 5 | AI2: ='1ST TERM Db'!W2 -> Biology | AN2: 6 | AO2: ='1ST TERM Db'!Z2 -> Physics | AT2: 7 | AU2: ='1ST TERM Db'!AC2 -> Financial Accounting | AZ2: 8 | BA2: ='1ST TERM Db'!AF2 -> Commerce | BF2: 9 | BG2: ='1ST TERM Db'!AI2 -> Economics | BL2: 10 | BM2: ='1ST TERM Db'!AL2 -> Government | BR2: 11 | BS2: ='1ST TERM Db'!AO2 -> Literature in English | BX2: 12 | BY2: ='1ST TERM Db'!AR2 -> CRS | CD2: 13 | CE2: ='1ST TERM Db'!AU2 -> IRS | CJ2: 14 | CK2: ='1ST TERM Db'!AX2 -> Geography | CP2: 15 | CQ2: ='1ST TERM Db'!BA2 -> Further Mathematics | CV2: 16 | CW2: ='1ST TERM Db'!BD2 -> Agricultural Science | DB2: 17 | DC2: ='1ST TERM Db'!BG2 -> Yoruba | DH2: 18 | DI2: ='1ST TERM Db'!BJ2 -> Data Processing | DP2: AFFECTIVE DOMAIN | DZ2: PSYCHOMOTOR DOMAIN
A3: S/N | B3: Name | C3: Admission Number | D3: Gender | E3: Class | F3: NO OF STUDENTS IN CLASS | G3: NO OF TIMES SCHOOL OPENED | H3: NO OF TIMES PRESENT | I3: NO OF TIMES ABSENT | J3: 3RD TERM C.A. (30%) | K3: 3RD TERM EXAM (70%) | L3: 3RD TERM TOTAL (100%) | M3: 2ND TERM TOTAL (100%) | N3: 1ST TERM TOTAL (100%) | O3: AVERAGE SCORE | P3: 3RD TERM C.A. (30%) | Q3: 3RD TERM EXAM (70%) | R3: 3RD TERM TOTAL (100%) | S3: 2ND TERM TOTAL (100%) | T3: 1ST TERM TOTAL (100%) | U3: AVERAGE SCORE | V3: 3RD TERM C.A. (30%) | W3: 3RD TERM EXAM (70%) | X3: 3RD TERM TOTAL (100%) | Y3: 2ND TERM TOTAL (100%) | Z3: 1ST TERM TOTAL (100%) | AA3: AVERAGE SCORE | AB3: 3RD TERM C.A. (30%) | AC3: 3RD TERM EXAM (70%) | AD3: 3RD TERM TOTAL (100%) | AE3: 2ND TERM TOTAL (100%) | AF3: 1ST TERM TOTAL (100%) | AG3: AVERAGE SCORE | AH3: 3RD TERM C.A. (30%) | AI3: 3RD TERM EXAM (70%) | AJ3: 3RD TERM TOTAL (100%) | AK3: 2ND TERM TOTAL (100%) | AL3: 1ST TERM TOTAL (100%) | AM3: AVERAGE SCORE | AN3: 3RD TERM C.A. (30%) | AO3: 3RD TERM EXAM (70%) | AP3: 3RD TERM TOTAL (100%) | AQ3: 2ND TERM TOTAL (100%) | AR3: 1ST TERM TOTAL (100%) | AS3: AVERAGE SCORE | AT3: 3RD TERM C.A. (30%) | AU3: 3RD TERM EXAM (70%) | AV3: 3RD TERM TOTAL (100%) | AW3: 2ND TERM TOTAL (100%) | AX3: 1ST TERM TOTAL (100%) | AY3: AVERAGE SCORE | AZ3: 3RD TERM C.A. (30%) | BA3: 3RD TERM EXAM (70%) | BB3: 3RD TERM TOTAL (100%) | BC3: 2ND TERM TOTAL (100%) | BD3: 1ST TERM TOTAL (100%) | BE3: AVERAGE SCORE | BF3: 3RD TERM C.A. (30%) | BG3: 3RD TERM EXAM (70%) | BH3: 3RD TERM TOTAL (100%) | BI3: 2ND TERM TOTAL (100%) | BJ3: 1ST TERM TOTAL (100%) | BK3: AVERAGE SCORE | BL3: 3RD TERM C.A. (30%) | BM3: 3RD TERM EXAM (70%) | BN3: 3RD TERM TOTAL (100%) | BO3: 2ND TERM TOTAL (100%) | BP3: 1ST TERM TOTAL (100%) | BQ3: AVERAGE SCORE | BR3: 3RD TERM C.A. (30%) | BS3: 3RD TERM EXAM (70%) | BT3: 3RD TERM TOTAL (100%) | BU3: 2ND TERM TOTAL (100%) | BV3: 1ST TERM TOTAL (100%) | BW3: AVERAGE SCORE | BX3: 3RD TERM C.A. (30%) | BY3: 3RD TERM EXAM (70%) | BZ3: 3RD TERM TOTAL (100%) | CA3: 2ND TERM TOTAL (100%) | CB3: 1ST TERM TOTAL (100%) | CC3: AVERAGE SCORE | CD3: 3RD TERM C.A. (30%) | CE3: 3RD TERM EXAM (70%) | CF3: 3RD TERM TOTAL (100%) | CG3: 2ND TERM TOTAL (100%) | CH3: 1ST TERM TOTAL (100%) | CI3: AVERAGE SCORE | CJ3: 3RD TERM C.A. (30%) | CK3: 3RD TERM EXAM (70%) | CL3: 3RD TERM TOTAL (100%) | CM3: 2ND TERM TOTAL (100%) | CN3: 1ST TERM TOTAL (100%) | CO3: AVERAGE SCORE | CP3: 3RD TERM C.A. (30%) | CQ3: 3RD TERM EXAM (70%) | CR3: 3RD TERM TOTAL (100%) | CS3: 2ND TERM TOTAL (100%) | CT3: 1ST TERM TOTAL (100%) | CU3: AVERAGE SCORE | CV3: 3RD TERM C.A. (30%) | CW3: 3RD TERM EXAM (70%) | CX3: 3RD TERM TOTAL (100%) | CY3: 2ND TERM TOTAL (100%) | CZ3: 1ST TERM TOTAL (100%) | DA3: AVERAGE SCORE | DB3: 3RD TERM C.A. (30%) | DC3: 3RD TERM EXAM (70%) | DD3: 3RD TERM TOTAL (100%) | DE3: 2ND TERM TOTAL (100%) | DF3: 1ST TERM TOTAL (100%) | DG3: AVERAGE SCORE | DH3: 3RD TERM C.A. (30%) | DI3: 3RD TERM EXAM (70%) | DJ3: 3RD TERM TOTAL (100%) | DK3: 2ND TERM TOTAL (100%) | DL3: 1ST TERM TOTAL (100%) | DM3: AVERAGE SCORE | DN3: TOTAL SCORE | DO3: POSITION | DP3: PUNCTUALITY | DQ3: NEATNESS | DR3: ATTENTIVENESS | DS3: RELATIONSHIP WITH OTHERS | DT3: POLITENESS | DU3: RESPONSIVENESS | DV3: COMMITMENT | DW3: CONSISTENCY | DX3: ACADEMIC SESSION | DY3: TERM | DZ3: CRAFTS/ DRAWING & PAINTING | EA3: TECHNICAL SKILLS | EB3: ICT SKILLS | EC3: GARDENING/ FARMING SKILLS | ED3: GAMES & SPORTS | EE3: CREATIVITY & INITIATIVE | EF3: VERBAL FLUENCY | EG3: CLASS TUTORS COMMENT | EH3: PRINCIPAL'S COMMENT | EI3: TUTOR'S NAME | EJ3: NEXT TERM BEGINS
A4: 1 | B4: ='1ST TERM Db'!B4 -> ADEBAYO JAMAL | C4: ='1ST TERM Db'!C4 -> 2806 | D4: ='1ST TERM Db'!D4 -> MALE | E4: ='1ST TERM Db'!E4 -> SSS3C | F4: 40 | G4: 224 | H4: 212 | I4: =G4-H4 -> 12 | J4: 23 | K4: 69 | L4: =SUM(J4:K4) -> 92 | M4: ='2ND TERM Db '!L4 -> 92 | N4: ='1ST TERM Db'!L4 -> 0 | O4: =IF(AND(L4=0,M4=0,N4=0),0,IF(AND(L4=0,M4=0),N4/1,IF(AND(L4=0,N4=0),M4/1,IF(AND(M4=0,N4=0),L4/1,IF(L4=0,FLOOR((M4+N4)/2,0.1),IF(M4=0,(L4+N4)/2,IF(N4=0,(M4+L4)/2,FLOOR(((L4+M4+N4)/3),0.1)))))))) -> 92 | P4: 16 | Q4: 56 | R4: =SUM(P4:Q4) -> 72 | S4: ='2ND TERM Db '!O4 -> 93 | T4: ='1ST TERM Db'!O4 -> 0 | U4: =IF(AND(R4=0,S4=0,T4=0),0,IF(AND(R4=0,S4=0),T4/1,IF(AND(R4=0,T4=0),S4/1,IF(AND(S4=0,T4=0),R4/1,IF(R4=0,FLOOR((S4+T4)/2,0.1),IF(S4=0,(R4+T4)/2,IF(T4=0,(S4+R4)/2,FLOOR(((R4+S4+T4)/3),0.1)))))))) -> 82.5 | V4: 23 | W4: 70 | X4: =SUM(V4:W4) -> 93 | Y4: ='2ND TERM Db '!R4 -> 100 | Z4: ='1ST TERM Db'!R4 -> 0 | AA4: =IF(AND(X4=0,Y4=0,Z4=0),0,IF(AND(X4=0,Y4=0),Z4/1,IF(AND(X4=0,Z4=0),Y4/1,IF(AND(Y4=0,Z4=0),X4/1,IF(X4=0,FLOOR((Y4+Z4)/2,0.1),IF(Y4=0,(X4+Z4)/2,IF(Z4=0,(Y4+X4)/2,FLOOR(((X4+Y4+Z4)/3),0.1)))))))) -> 96.5 | AB4: 27 | AC4: 62 | AD4: =SUM(AB4:AC4) -> 89 | AE4: ='2ND TERM Db '!U4 -> 95 | AF4: ='1ST TERM Db'!U4 -> 0 | AG4: =IF(AND(AD4=0,AE4=0,AF4=0),0,IF(AND(AD4=0,AE4=0),AF4/1,IF(AND(AD4=0,AF4=0),AE4/1,IF(AND(AE4=0,AF4=0),AD4/1,IF(AD4=0,FLOOR((AE4+AF4)/2,0.1),IF(AE4=0,(AD4+AF4)/2,IF(AF4=0,(AE4+AD4)/2,FLOOR(((AD4+AE4+AF4)/3),0.1)))))))) -> 92 | AH4: 20 | AI4: 46 | AJ4: =SUM(AH4:AI4) -> 66 | AK4: ='2ND TERM Db '!X4 -> 75 | AL4: ='1ST TERM Db'!X4 -> 0 | AM4: =IF(AND(AJ4=0,AK4=0,AL4=0),0,IF(AND(AJ4=0,AK4=0),AL4/1,IF(AND(AJ4=0,AL4=0),AK4/1,IF(AND(AK4=0,AL4=0),AJ4/1,IF(AJ4=0,FLOOR((AK4+AL4)/2,0.1),IF(AK4=0,(AJ4+AL4)/2,IF(AL4=0,(AK4+AJ4)/2,FLOOR(((AJ4+AK4+AL4)/3),0.1)))))))) -> 70.5 | AP4: =SUM(AN4:AO4) -> 0 | AQ4: ='2ND TERM Db '!AA4 -> 84 | AR4: ='1ST TERM Db'!AA4 -> 0 | AS4: =IF(AND(AP4=0,AQ4=0,AR4=0),0,IF(AND(AP4=0,AQ4=0),AR4/1,IF(AND(AP4=0,AR4=0),AQ4/1,IF(AND(AQ4=0,AR4=0),AP4/1,IF(AP4=0,FLOOR((AQ4+AR4)/2,0.1),IF(AQ4=0,(AP4+AR4)/2,IF(AR4=0,(AQ4+AP4)/2,FLOOR(((AP4+AQ4+AR4)/3),0.1)))))))) -> 84 | AT4: 12 | AU4: 34 | AV4: =SUM(AT4:AU4) -> 46 | AW4: ='2ND TERM Db '!AD4 -> 74 | AX4: ='1ST TERM Db'!AD4 -> 0 | AY4: =IF(AND(AV4=0,AW4=0,AX4=0),0,IF(AND(AV4=0,AW4=0),AX4/1,IF(AND(AV4=0,AX4=0),AW4/1,IF(AND(AW4=0,AX4=0),AV4/1,IF(AV4=0,FLOOR((AW4+AX4)/2,0.1),IF(AW4=0,(AV4+AX4)/2,IF(AX4=0,(AW4+AV4)/2,FLOOR(((AV4+AW4+AX4)/3),0.1)))))))) -> 60 | AZ4: 20 | BA4: 34 | BB4: =SUM(AZ4:BA4) -> 54 | BC4: ='2ND TERM Db '!AG4 -> 89 | BD4: ='1ST TERM Db'!AG4 -> 0 | BE4: =IF(AND(BB4=0,BC4=0,BD4=0),0,IF(AND(BB4=0,BC4=0),BD4/1,IF(AND(BB4=0,BD4=0),BC4/1,IF(AND(BC4=0,BD4=0),BB4/1,IF(BB4=0,FLOOR((BC4+BD4)/2,0.1),IF(BC4=0,(BB4+BD4)/2,IF(BD4=0,(BC4+BB4)/2,FLOOR(((BB4+BC4+BD4)/3),0.1)))))))) -> 71.5 | BF4: 11 | BG4: 23 | BH4: =SUM(BF4:BG4) -> 34 | BI4: ='2ND TERM Db '!AJ4 -> 35 | BJ4: ='1ST TERM Db'!AJ4 -> 43 | BK4: =IF(AND(BH4=0,BI4=0,BJ4=0),0,IF(AND(BH4=0,BI4=0),BJ4/1,IF(AND(BH4=0,BJ4=0),BI4/1,IF(AND(BI4=0,BJ4=0),BH4/1,IF(BH4=0,FLOOR((BI4+BJ4)/2,0.1),IF(BI4=0,(BH4+BJ4)/2,IF(BJ4=0,(BI4+BH4)/2,FLOOR(((BH4+BI4+BJ4)/3),0.1)))))))) -> 37.3 | BL4: 23 | BM4: 60 | BN4: =SUM(BL4:BM4) -> 83 | BO4: ='2ND TERM Db '!AM4 -> 90 | BP4: ='1ST TERM Db'!AM4 -> 0 | BQ4: =IF(AND(BN4=0,BO4=0,BP4=0),0,IF(AND(BN4=0,BO4=0),BP4/1,IF(AND(BN4=0,BP4=0),BO4/1,IF(AND(BO4=0,BP4=0),BN4/1,IF(BN4=0,FLOOR((BO4+BP4)/2,0.1),IF(BO4=0,(BN4+BP4)/2,IF(BP4=0,(BO4+BN4)/2,FLOOR(((BN4+BO4+BP4)/3),0.1)))))))) -> 86.5 | BR4: 12 | BS4: 23 | BT4: =SUM(BR4:BS4) -> 35 | BU4: ='2ND TERM Db '!AP4 -> 47 | BV4: ='1ST TERM Db'!AP4 -> 0 | BW4: =IF(AND(BT4=0,BU4=0,BV4=0),0,IF(AND(BT4=0,BU4=0),BV4/1,IF(AND(BT4=0,BV4=0),BU4/1,IF(AND(BU4=0,BV4=0),BT4/1,IF(BT4=0,FLOOR((BU4+BV4)/2,0.1),IF(BU4=0,(BT4+BV4)/2,IF(BV4=0,(BU4+BT4)/2,FLOOR(((BT4+BU4+BV4)/3),0.1)))))))) -> 41 | BX4: 0 | BY4: 0 | BZ4: =SUM(BX4:BY4) -> 0 | CA4: ='2ND TERM Db '!AS4 -> 0 | CB4: ='1ST TERM Db'!AS4 -> 0 | CC4: =IF(AND(BZ4=0,CA4=0,CB4=0),0,IF(AND(BZ4=0,CA4=0),CB4/1,IF(AND(BZ4=0,CB4=0),CA4/1,IF(AND(CA4=0,CB4=0),BZ4/1,IF(BZ4=0,FLOOR((CA4+CB4)/2,0.1),IF(CA4=0,(BZ4+CB4)/2,IF(CB4=0,(CA4+BZ4)/2,FLOOR(((BZ4+CA4+CB4)/3),0.1)))))))) -> 0 | CD4: 0 | CE4: 0 | CF4: =SUM(CD4:CE4) -> 0 | CG4: ='2ND TERM Db '!AV4 -> 0 | CH4: ='1ST TERM Db'!AV4 -> 0 | CI4: =IF(AND(CF4=0,CG4=0,CH4=0),0,IF(AND(CF4=0,CG4=0),CH4/1,IF(AND(CF4=0,CH4=0),CG4/1,IF(AND(CG4=0,CH4=0),CF4/1,IF(CF4=0,FLOOR((CG4+CH4)/2,0.1),IF(CG4=0,(CF4+CH4)/2,IF(CH4=0,(CG4+CF4)/2,FLOOR(((CF4+CG4+CH4)/3),0.1)))))))) -> 0 | CJ4: 0 | CK4: 0 | CL4: =SUM(CJ4:CK4) -> 0 | CM4: ='2ND TERM Db '!AY4 -> 0 | CN4: ='1ST TERM Db'!AY4 -> 0 | CO4: =IF(AND(CL4=0,CM4=0,CN4=0),0,IF(AND(CL4=0,CM4=0),CN4/1,IF(AND(CL4=0,CN4=0),CM4/1,IF(AND(CM4=0,CN4=0),CL4/1,IF(CL4=0,FLOOR((CM4+CN4)/2,0.1),IF(CM4=0,(CL4+CN4)/2,IF(CN4=0,(CM4+CL4)/2,FLOOR(((CL4+CM4+CN4)/3),0.1)))))))) -> 0 | CP4: 0 | CQ4: 0 | CR4: =SUM(CP4:CQ4) -> 0 | CS4: ='2ND TERM Db '!BB4 -> 0 | CT4: ='1ST TERM Db'!BB4 -> 0 | CU4: =IF(AND(CR4=0,CS4=0,CT4=0),0,IF(AND(CR4=0,CS4=0),CT4/1,IF(AND(CR4=0,CT4=0),CS4/1,IF(AND(CS4=0,CT4=0),CR4/1,IF(CR4=0,FLOOR((CS4+CT4)/2,0.1),IF(CS4=0,(CR4+CT4)/2,IF(CT4=0,(CS4+CR4)/2,FLOOR(((CR4+CS4+CT4)/3),0.1)))))))) -> 0 | CV4: 0 | CW4: 0 | CX4: =SUM(CV4:CW4) -> 0 | CY4: ='2ND TERM Db '!BE4 -> 0 | CZ4: ='1ST TERM Db'!BE4 -> 0 | DA4: =IF(AND(CX4=0,CY4=0,CZ4=0),0,IF(AND(CX4=0,CY4=0),CZ4/1,IF(AND(CX4=0,CZ4=0),CY4/1,IF(AND(CY4=0,CZ4=0),CX4/1,IF(CX4=0,FLOOR((CY4+CZ4)/2,0.1),IF(CY4=0,(CX4+CZ4)/2,IF(CZ4=0,(CY4+CX4)/2,FLOOR(((CX4+CY4+CZ4)/3),0.1)))))))) -> 0 | DB4: 0 | DC4: 0 | DD4: =SUM(DB4:DC4) -> 0 | DE4: ='2ND TERM Db '!BH4 -> 0 | DF4: ='1ST TERM Db'!BH4 -> 0 | DG4: =IF(AND(DD4=0,DE4=0,DF4=0),0,IF(AND(DD4=0,DE4=0),DF4/1,IF(AND(DD4=0,DF4=0),DE4/1,IF(AND(DE4=0,DF4=0),DD4/1,IF(DD4=0,FLOOR((DE4+DF4)/2,0.1),IF(DE4=0,(DD4+DF4)/2,IF(DF4=0,(DE4+DD4)/2,FLOOR(((DD4+DE4+DF4)/3),0.1)))))))) -> 0 | DH4: 0 | DI4: 0 | DJ4: =SUM(DH4:DI4) -> 0 | DK4: ='2ND TERM Db '!BK4 -> 0 | DL4: ='1ST TERM Db'!BK4 -> 0 | DM4: =IF(AND(DJ4=0,DK4=0,DL4=0),0,IF(AND(DJ4=0,DK4=0),DL4/1,IF(AND(DJ4=0,DL4=0),DK4/1,IF(AND(DK4=0,DL4=0),DJ4/1,IF(DJ4=0,FLOOR((DK4+DL4)/2,0.1),IF(DK4=0,(DJ4+DL4)/2,IF(DL4=0,(DK4+DJ4)/2,FLOOR(((DJ4+DK4+DL4)/3),0.1)))))))) -> 0 | DN4: =SUM(O4,U4,AA4,AG4,AM4,AS4,AY4,BE4,BK4,BQ4,BW4,CC4,CI4,CO4,CU4,DA4,DG4:DM4) -> 813.8 | DO4: =RANK(DN4,DN4:DN503,0) -> 1 | DP4: EXCELLENT(5) | DQ4: EXCELLENT(5) | DR4: GOOD(4) | DS4: AVERAGE(3) | DT4: GOOD(4) | DU4: GOOD(4) | DV4: GOOD(4) | DW4: EXCELLENT(5) | DX4: 2025/2026 | DY4: THIRD | DZ4: GOOD(4) | EA4: OPTIONAL | EB4: OPTIONAL | EC4: GOOD(4) | ED4: GOOD(4) | EE4: AVERAGE(3) | EF4: GOOD(4) | EG4: Add the Tutor's Comment . . . | EH4: Choose Principals comment | EI4: Mr. Akinwale Ibrahim | EJ4: Next Term Begins on Monday, 14th September, 2026.
A5: 2 | B5: ='1ST TERM Db'!B5 -> GANIYU DAMILARE | C5: ='1ST TERM Db'!C5 -> 2809 | D5: ='1ST TERM Db'!D5 -> MALE | E5: ='1ST TERM Db'!E5 -> SSS3C | F5: 40 | G5: 224 | H5: 212 | I5: =G5-H5 -> 12 | J5: 21 | K5: 45 | L5: =SUM(J5:K5) -> 66 | M5: ='2ND TERM Db '!L5 -> 66 | N5: ='1ST TERM Db'!L5 -> 0 | O5: =IF(AND(L5=0,M5=0,N5=0),0,IF(AND(L5=0,M5=0),N5/1,IF(AND(L5=0,N5=0),M5/1,IF(AND(M5=0,N5=0),L5/1,IF(L5=0,FLOOR((M5+N5)/2,0.1),IF(M5=0,(L5+N5)/2,IF(N5=0,(M5+L5)/2,FLOOR(((L5+M5+N5)/3),0.1)))))))) -> 66 | P5: 23 | Q5: 45 | R5: =SUM(P5:Q5) -> 68 | S5: ='2ND TERM Db '!O5 -> 88 | T5: ='1ST TERM Db'!O5 -> 0 | U5: =IF(AND(R5=0,S5=0,T5=0),0,IF(AND(R5=0,S5=0),T5/1,IF(AND(R5=0,T5=0),S5/1,IF(AND(S5=0,T5=0),R5/1,IF(R5=0,FLOOR((S5+T5)/2,0.1),IF(S5=0,(R5+T5)/2,IF(T5=0,(S5+R5)/2,FLOOR(((R5+S5+T5)/3),0.1)))))))) -> 78 | V5: 19 | W5: 46 | X5: =SUM(V5:W5) -> 65 | Y5: ='2ND TERM Db '!R5 -> 80 | Z5: ='1ST TERM Db'!R5 -> 0 | AA5: =IF(AND(X5=0,Y5=0,Z5=0),0,IF(AND(X5=0,Y5=0),Z5/1,IF(AND(X5=0,Z5=0),Y5/1,IF(AND(Y5=0,Z5=0),X5/1,IF(X5=0,FLOOR((Y5+Z5)/2,0.1),IF(Y5=0,(X5+Z5)/2,IF(Z5=0,(Y5+X5)/2,FLOOR(((X5+Y5+Z5)/3),0.1)))))))) -> 72.5 | AB5: 10 | AC5: 32 | AD5: =SUM(AB5:AC5) -> 42 | AE5: ='2ND TERM Db '!U5 -> 75 | AF5: ='1ST TERM Db'!U5 -> 0 | AG5: =IF(AND(AD5=0,AE5=0,AF5=0),0,IF(AND(AD5=0,AE5=0),AF5/1,IF(AND(AD5=0,AF5=0),AE5/1,IF(AND(AE5=0,AF5=0),AD5/1,IF(AD5=0,FLOOR((AE5+AF5)/2,0.1),IF(AE5=0,(AD5+AF5)/2,IF(AF5=0,(AE5+AD5)/2,FLOOR(((AD5+AE5+AF5)/3),0.1)))))))) -> 58.5 | AH5: 23 | AI5: 24 | AJ5: =SUM(AH5:AI5) -> 47 | AK5: ='2ND TERM Db '!X5 -> 66 | AL5: ='1ST TERM Db'!X5 -> 0 | AM5: =IF(AND(AJ5=0,AK5=0,AL5=0),0,IF(AND(AJ5=0,AK5=0),AL5/1,IF(AND(AJ5=0,AL5=0),AK5/1,IF(AND(AK5=0,AL5=0),AJ5/1,IF(AJ5=0,FLOOR((AK5+AL5)/2,0.1),IF(AK5=0,(AJ5+AL5)/2,IF(AL5=0,(AK5+AJ5)/2,FLOOR(((AJ5+AK5+AL5)/3),0.1)))))))) -> 56.5 | AN5: 16 | AO5: 40 | AP5: =SUM(AN5:AO5) -> 56 | AQ5: ='2ND TERM Db '!AA5 -> 72 | AR5: ='1ST TERM Db'!AA5 -> 0 | AS5: =IF(AND(AP5=0,AQ5=0,AR5=0),0,IF(AND(AP5=0,AQ5=0),AR5/1,IF(AND(AP5=0,AR5=0),AQ5/1,IF(AND(AQ5=0,AR5=0),AP5/1,IF(AP5=0,FLOOR((AQ5+AR5)/2,0.1),IF(AQ5=0,(AP5+AR5)/2,IF(AR5=0,(AQ5+AP5)/2,FLOOR(((AP5+AQ5+AR5)/3),0.1)))))))) -> 64 | AT5: 21 | AU5: 45 | AV5: =SUM(AT5:AU5) -> 66 | AW5: ='2ND TERM Db '!AD5 -> 84 | AX5: ='1ST TERM Db'!AD5 -> 0 | AY5: =IF(AND(AV5=0,AW5=0,AX5=0),0,IF(AND(AV5=0,AW5=0),AX5/1,IF(AND(AV5=0,AX5=0),AW5/1,IF(AND(AW5=0,AX5=0),AV5/1,IF(AV5=0,FLOOR((AW5+AX5)/2,0.1),IF(AW5=0,(AV5+AX5)/2,IF(AX5=0,(AW5+AV5)/2,FLOOR(((AV5+AW5+AX5)/3),0.1)))))))) -> 75 | AZ5: 24 | BA5: 39 | BB5: =SUM(AZ5:BA5) -> 63 | BC5: ='2ND TERM Db '!AG5 -> 78 | BD5: ='1ST TERM Db'!AG5 -> 0 | BE5: =IF(AND(BB5=0,BC5=0,BD5=0),0,IF(AND(BB5=0,BC5=0),BD5/1,IF(AND(BB5=0,BD5=0),BC5/1,IF(AND(BC5=0,BD5=0),BB5/1,IF(BB5=0,FLOOR((BC5+BD5)/2,0.1),IF(BC5=0,(BB5+BD5)/2,IF(BD5=0,(BC5+BB5)/2,FLOOR(((BB5+BC5+BD5)/3),0.1)))))))) -> 70.5 | BF5: 20 | BG5: 40 | BH5: =SUM(BF5:BG5) -> 60 | BI5: ='2ND TERM Db '!AJ5 -> 79 | BJ5: ='1ST TERM Db'!AJ5 -> 41 | BK5: =IF(AND(BH5=0,BI5=0,BJ5=0),0,IF(AND(BH5=0,BI5=0),BJ5/1,IF(AND(BH5=0,BJ5=0),BI5/1,IF(AND(BI5=0,BJ5=0),BH5/1,IF(BH5=0,FLOOR((BI5+BJ5)/2,0.1),IF(BI5=0,(BH5+BJ5)/2,IF(BJ5=0,(BI5+BH5)/2,FLOOR(((BH5+BI5+BJ5)/3),0.1)))))))) -> 60 | BN5: =SUM(BL5:BM5) -> 0 | BO5: ='2ND TERM Db '!AM5 -> 0 | BP5: ='1ST TERM Db'!AM5 -> 0 | BQ5: =IF(AND(BN5=0,BO5=0,BP5=0),0,IF(AND(BN5=0,BO5=0),BP5/1,IF(AND(BN5=0,BP5=0),BO5/1,IF(AND(BO5=0,BP5=0),BN5/1,IF(BN5=0,FLOOR((BO5+BP5)/2,0.1),IF(BO5=0,(BN5+BP5)/2,IF(BP5=0,(BO5+BN5)/2,FLOOR(((BN5+BO5+BP5)/3),0.1)))))))) -> 0 | BT5: =SUM(BR5:BS5) -> 0 | BU5: ='2ND TERM Db '!AP5 -> 0 | BV5: ='1ST TERM Db'!AP5 -> 0 | BW5: =IF(AND(BT5=0,BU5=0,BV5=0),0,IF(AND(BT5=0,BU5=0),BV5/1,IF(AND(BT5=0,BV5=0),BU5/1,IF(AND(BU5=0,BV5=0),BT5/1,IF(BT5=0,FLOOR((BU5+BV5)/2,0.1),IF(BU5=0,(BT5+BV5)/2,IF(BV5=0,(BU5+BT5)/2,FLOOR(((BT5+BU5+BV5)/3),0.1)))))))) -> 0 | BX5: 0 | BY5: 0 | BZ5: =SUM(BX5:BY5) -> 0 | CA5: ='2ND TERM Db '!AS5 -> 0 | CB5: ='1ST TERM Db'!AS5 -> 0 | CC5: =IF(AND(BZ5=0,CA5=0,CB5=0),0,IF(AND(BZ5=0,CA5=0),CB5/1,IF(AND(BZ5=0,CB5=0),CA5/1,IF(AND(CA5=0,CB5=0),BZ5/1,IF(BZ5=0,FLOOR((CA5+CB5)/2,0.1),IF(CA5=0,(BZ5+CB5)/2,IF(CB5=0,(CA5+BZ5)/2,FLOOR(((BZ5+CA5+CB5)/3),0.1)))))))) -> 0 | CD5: 0 | CE5: 0 | CF5: =SUM(CD5:CE5) -> 0 | CG5: ='2ND TERM Db '!AV5 -> 0 | CH5: ='1ST TERM Db'!AV5 -> 0 | CI5: =IF(AND(CF5=0,CG5=0,CH5=0),0,IF(AND(CF5=0,CG5=0),CH5/1,IF(AND(CF5=0,CH5=0),CG5/1,IF(AND(CG5=0,CH5=0),CF5/1,IF(CF5=0,FLOOR((CG5+CH5)/2,0.1),IF(CG5=0,(CF5+CH5)/2,IF(CH5=0,(CG5+CF5)/2,FLOOR(((CF5+CG5+CH5)/3),0.1)))))))) -> 0 | CJ5: 0 | CK5: 0 | CL5: =SUM(CJ5:CK5) -> 0 | CM5: ='2ND TERM Db '!AY5 -> 0 | CN5: ='1ST TERM Db'!AY5 -> 0 | CO5: =IF(AND(CL5=0,CM5=0,CN5=0),0,IF(AND(CL5=0,CM5=0),CN5/1,IF(AND(CL5=0,CN5=0),CM5/1,IF(AND(CM5=0,CN5=0),CL5/1,IF(CL5=0,FLOOR((CM5+CN5)/2,0.1),IF(CM5=0,(CL5+CN5)/2,IF(CN5=0,(CM5+CL5)/2,FLOOR(((CL5+CM5+CN5)/3),0.1)))))))) -> 0 | CP5: 0 | CQ5: 0 | CR5: =SUM(CP5:CQ5) -> 0 | CS5: ='2ND TERM Db '!BB5 -> 0 | CT5: ='1ST TERM Db'!BB5 -> 0 | CU5: =IF(AND(CR5=0,CS5=0,CT5=0),0,IF(AND(CR5=0,CS5=0),CT5/1,IF(AND(CR5=0,CT5=0),CS5/1,IF(AND(CS5=0,CT5=0),CR5/1,IF(CR5=0,FLOOR((CS5+CT5)/2,0.1),IF(CS5=0,(CR5+CT5)/2,IF(CT5=0,(CS5+CR5)/2,FLOOR(((CR5+CS5+CT5)/3),0.1)))))))) -> 0 | CV5: 0 | CW5: 0 | CX5: =SUM(CV5:CW5) -> 0 | CY5: ='2ND TERM Db '!BE5 -> 0 | CZ5: ='1ST TERM Db'!BE5 -> 0 | DA5: =IF(AND(CX5=0,CY5=0,CZ5=0),0,IF(AND(CX5=0,CY5=0),CZ5/1,IF(AND(CX5=0,CZ5=0),CY5/1,IF(AND(CY5=0,CZ5=0),CX5/1,IF(CX5=0,FLOOR((CY5+CZ5)/2,0.1),IF(CY5=0,(CX5+CZ5)/2,IF(CZ5=0,(CY5+CX5)/2,FLOOR(((CX5+CY5+CZ5)/3),0.1)))))))) -> 0 | DB5: 0 | DC5: 0 | DD5: =SUM(DB5:DC5) -> 0 | DE5: ='2ND TERM Db '!BH5 -> 0 | DF5: ='1ST TERM Db'!BH5 -> 0 | DG5: =IF(AND(DD5=0,DE5=0,DF5=0),0,IF(AND(DD5=0,DE5=0),DF5/1,IF(AND(DD5=0,DF5=0),DE5/1,IF(AND(DE5=0,DF5=0),DD5/1,IF(DD5=0,FLOOR((DE5+DF5)/2,0.1),IF(DE5=0,(DD5+DF5)/2,IF(DF5=0,(DE5+DD5)/2,FLOOR(((DD5+DE5+DF5)/3),0.1)))))))) -> 0 | DH5: 0 | DI5: 0 | DJ5: =SUM(DH5:DI5) -> 0 | DK5: ='2ND TERM Db '!BK5 -> 0 | DL5: ='1ST TERM Db'!BK5 -> 0 | DM5: =IF(AND(DJ5=0,DK5=0,DL5=0),0,IF(AND(DJ5=0,DK5=0),DL5/1,IF(AND(DJ5=0,DL5=0),DK5/1,IF(AND(DK5=0,DL5=0),DJ5/1,IF(DJ5=0,FLOOR((DK5+DL5)/2,0.1),IF(DK5=0,(DJ5+DL5)/2,IF(DL5=0,(DK5+DJ5)/2,FLOOR(((DJ5+DK5+DL5)/3),0.1)))))))) -> 0 | DN5: =SUM(O5,U5,AA5,AG5,AM5,AS5,AY5,BE5,BK5,BQ5,BW5,CC5,CI5,CO5,CU5,DA5,DG5,DM5) -> 601 | DO5: =RANK(DN5,DN$4:DN$503) -> 2 | DP5: GOOD(4) | DQ5: EXCELLENT(5) | DR5: GOOD(4) | DS5: GOOD(4) | DT5: GOOD(4) | DU5: GOOD(4) | DV5: GOOD(4) | DW5: GOOD(4) | DX5: 2025/2026 | DY5: THIRD | DZ5: OPTIONAL | EA5: GOOD(4) | EB5: GOOD(4) | EC5: AVERAGE(3) | ED5: GOOD(4) | EE5: GOOD(4) | EF5: GOOD(4) | EG5: Add the Tutor's Comment . . . | EH5: Choose Principals comment | EI5: Mr. Akinwale Ibrahim | EJ5: Next Term Begins on Monday, 14th September, 2026.
A6: 3 | B6: ='1ST TERM Db'!B6 -> ISHOLA ROKEEB | C6: ='1ST TERM Db'!C6 -> 2360 | D6: ='1ST TERM Db'!D6 -> MALE | E6: ='1ST TERM Db'!E6 -> SSS3C | I6: =G6-H6 -> 0 | L6: =SUM(J6:K6) -> 0 | M6: ='2ND TERM Db '!L6 -> 0 | N6: ='1ST TERM Db'!L6 -> 0 | O6: =IF(AND(L6=0,M6=0,N6=0),0,IF(AND(L6=0,M6=0),N6/1,IF(AND(L6=0,N6=0),M6/1,IF(AND(M6=0,N6=0),L6/1,IF(L6=0,FLOOR((M6+N6)/2,0.1),IF(M6=0,(L6+N6)/2,IF(N6=0,(M6+L6)/2,FLOOR(((L6+M6+N6)/3),0.1)))))))) -> 0 | R6: =SUM(P6:Q6) -> 0 | S6: ='2ND TERM Db '!O6 -> 0 | T6: ='1ST TERM Db'!O6 -> 0 | U6: =IF(AND(R6=0,S6=0,T6=0),0,IF(AND(R6=0,S6=0),T6/1,IF(AND(R6=0,T6=0),S6/1,IF(AND(S6=0,T6=0),R6/1,IF(R6=0,FLOOR((S6+T6)/2,0.1),IF(S6=0,(R6+T6)/2,IF(T6=0,(S6+R6)/2,FLOOR(((R6+S6+T6)/3),0.1)))))))) -> 0 | X6: =SUM(V6:W6) -> 0 | Y6: ='2ND TERM Db '!R6 -> 0 | Z6: ='1ST TERM Db'!R6 -> 0 | AA6: =IF(AND(X6=0,Y6=0,Z6=0),0,IF(AND(X6=0,Y6=0),Z6/1,IF(AND(X6=0,Z6=0),Y6/1,IF(AND(Y6=0,Z6=0),X6/1,IF(X6=0,FLOOR((Y6+Z6)/2,0.1),IF(Y6=0,(X6+Z6)/2,IF(Z6=0,(Y6+X6)/2,FLOOR(((X6+Y6+Z6)/3),0.1)))))))) -> 0 | AD6: =SUM(AB6:AC6) -> 0 | AE6: ='2ND TERM Db '!U6 -> 0 | AF6: ='1ST TERM Db'!U6 -> 0 | AG6: =IF(AND(AD6=0,AE6=0,AF6=0),0,IF(AND(AD6=0,AE6=0),AF6/1,IF(AND(AD6=0,AF6=0),AE6/1,IF(AND(AE6=0,AF6=0),AD6/1,IF(AD6=0,FLOOR((AE6+AF6)/2,0.1),IF(AE6=0,(AD6+AF6)/2,IF(AF6=0,(AE6+AD6)/2,FLOOR(((AD6+AE6+AF6)/3),0.1)))))))) -> 0 | AJ6: =SUM(AH6:AI6) -> 0 | AK6: ='2ND TERM Db '!X6 -> 0 | AL6: ='1ST TERM Db'!X6 -> 0 | AM6: =IF(AND(AJ6=0,AK6=0,AL6=0),0,IF(AND(AJ6=0,AK6=0),AL6/1,IF(AND(AJ6=0,AL6=0),AK6/1,IF(AND(AK6=0,AL6=0),AJ6/1,IF(AJ6=0,FLOOR((AK6+AL6)/2,0.1),IF(AK6=0,(AJ6+AL6)/2,IF(AL6=0,(AK6+AJ6)/2,FLOOR(((AJ6+AK6+AL6)/3),0.1)))))))) -> 0 | AP6: =SUM(AN6:AO6) -> 0 | AQ6: ='2ND TERM Db '!AA6 -> 0 | AR6: ='1ST TERM Db'!AA6 -> 0 | AS6: =IF(AND(AP6=0,AQ6=0,AR6=0),0,IF(AND(AP6=0,AQ6=0),AR6/1,IF(AND(AP6=0,AR6=0),AQ6/1,IF(AND(AQ6=0,AR6=0),AP6/1,IF(AP6=0,FLOOR((AQ6+AR6)/2,0.1),IF(AQ6=0,(AP6+AR6)/2,IF(AR6=0,(AQ6+AP6)/2,FLOOR(((AP6+AQ6+AR6)/3),0.1)))))))) -> 0 | AV6: =SUM(AT6:AU6) -> 0 | AW6: ='2ND TERM Db '!AD6 -> 0 | AX6: ='1ST TERM Db'!AD6 -> 0 | AY6: =IF(AND(AV6=0,AW6=0,AX6=0),0,IF(AND(AV6=0,AW6=0),AX6/1,IF(AND(AV6=0,AX6=0),AW6/1,IF(AND(AW6=0,AX6=0),AV6/1,IF(AV6=0,FLOOR((AW6+AX6)/2,0.1),IF(AW6=0,(AV6+AX6)/2,IF(AX6=0,(AW6+AV6)/2,FLOOR(((AV6+AW6+AX6)/3),0.1)))))))) -> 0 | BB6: =SUM(AZ6:BA6) -> 0 | BC6: ='2ND TERM Db '!AG6 -> 0 | BD6: ='1ST TERM Db'!AG6 -> 0 | BE6: =IF(AND(BB6=0,BC6=0,BD6=0),0,IF(AND(BB6=0,BC6=0),BD6/1,IF(AND(BB6=0,BD6=0),BC6/1,IF(AND(BC6=0,BD6=0),BB6/1,IF(BB6=0,FLOOR((BC6+BD6)/2,0.1),IF(BC6=0,(BB6+BD6)/2,IF(BD6=0,(BC6+BB6)/2,FLOOR(((BB6+BC6+BD6)/3),0.1)))))))) -> 0 | BH6: =SUM(BF6:BG6) -> 0 | BI6: ='2ND TERM Db '!AJ6 -> 0 | BJ6: ='1ST TERM Db'!AJ6 -> 0 | BK6: =IF(AND(BH6=0,BI6=0,BJ6=0),0,IF(AND(BH6=0,BI6=0),BJ6/1,IF(AND(BH6=0,BJ6=0),BI6/1,IF(AND(BI6=0,BJ6=0),BH6/1,IF(BH6=0,FLOOR((BI6+BJ6)/2,0.1),IF(BI6=0,(BH6+BJ6)/2,IF(BJ6=0,(BI6+BH6)/2,FLOOR(((BH6+BI6+BJ6)/3),0.1)))))))) -> 0 | BN6: =SUM(BL6:BM6) -> 0 | BO6: ='2ND TERM Db '!AM6 -> 0 | BP6: ='1ST TERM Db'!AM6 -> 0 | BQ6: =IF(AND(BN6=0,BO6=0,BP6=0),0,IF(AND(BN6=0,BO6=0),BP6/1,IF(AND(BN6=0,BP6=0),BO6/1,IF(AND(BO6=0,BP6=0),BN6/1,IF(BN6=0,FLOOR((BO6+BP6)/2,0.1),IF(BO6=0,(BN6+BP6)/2,IF(BP6=0,(BO6+BN6)/2,FLOOR(((BN6+BO6+BP6)/3),0.1)))))))) -> 0 | BT6: =SUM(BR6:BS6) -> 0 | BU6: ='2ND TERM Db '!AP6 -> 0 | BV6: ='1ST TERM Db'!AP6 -> 0 | BW6: =IF(AND(BT6=0,BU6=0,BV6=0),0,IF(AND(BT6=0,BU6=0),BV6/1,IF(AND(BT6=0,BV6=0),BU6/1,IF(AND(BU6=0,BV6=0),BT6/1,IF(BT6=0,FLOOR((BU6+BV6)/2,0.1),IF(BU6=0,(BT6+BV6)/2,IF(BV6=0,(BU6+BT6)/2,FLOOR(((BT6+BU6+BV6)/3),0.1)))))))) -> 0 | BZ6: =SUM(BX6:BY6) -> 0 | CA6: ='2ND TERM Db '!AS6 -> 0 | CB6: ='1ST TERM Db'!AS6 -> 0 | CC6: =IF(AND(BZ6=0,CA6=0,CB6=0),0,IF(AND(BZ6=0,CA6=0),CB6/1,IF(AND(BZ6=0,CB6=0),CA6/1,IF(AND(CA6=0,CB6=0),BZ6/1,IF(BZ6=0,FLOOR((CA6+CB6)/2,0.1),IF(CA6=0,(BZ6+CB6)/2,IF(CB6=0,(CA6+BZ6)/2,FLOOR(((BZ6+CA6+CB6)/3),0.1)))))))) -> 0 | CF6: =SUM(CD6:CE6) -> 0 | CG6: ='2ND TERM Db '!AV6 -> 0 | CH6: ='1ST TERM Db'!AV6 -> 0 | CI6: =IF(AND(CF6=0,CG6=0,CH6=0),0,IF(AND(CF6=0,CG6=0),CH6/1,IF(AND(CF6=0,CH6=0),CG6/1,IF(AND(CG6=0,CH6=0),CF6/1,IF(CF6=0,FLOOR((CG6+CH6)/2,0.1),IF(CG6=0,(CF6+CH6)/2,IF(CH6=0,(CG6+CF6)/2,FLOOR(((CF6+CG6+CH6)/3),0.1)))))))) -> 0 | CL6: =SUM(CJ6:CK6) -> 0 | CM6: ='2ND TERM Db '!AY6 -> 0 | CN6: ='1ST TERM Db'!AY6 -> 0 | CO6: =IF(AND(CL6=0,CM6=0,CN6=0),0,IF(AND(CL6=0,CM6=0),CN6/1,IF(AND(CL6=0,CN6=0),CM6/1,IF(AND(CM6=0,CN6=0),CL6/1,IF(CL6=0,FLOOR((CM6+CN6)/2,0.1),IF(CM6=0,(CL6+CN6)/2,IF(CN6=0,(CM6+CL6)/2,FLOOR(((CL6+CM6+CN6)/3),0.1)))))))) -> 0 | CR6: =SUM(CP6:CQ6) -> 0 | CS6: ='2ND TERM Db '!BB6 -> 0 | CT6: ='1ST TERM Db'!BB6 -> 0 | CU6: =IF(AND(CR6=0,CS6=0,CT6=0),0,IF(AND(CR6=0,CS6=0),CT6/1,IF(AND(CR6=0,CT6=0),CS6/1,IF(AND(CS6=0,CT6=0),CR6/1,IF(CR6=0,FLOOR((CS6+CT6)/2,0.1),IF(CS6=0,(CR6+CT6)/2,IF(CT6=0,(CS6+CR6)/2,FLOOR(((CR6+CS6+CT6)/3),0.1)))))))) -> 0 | CX6: =SUM(CV6:CW6) -> 0 | CY6: ='2ND TERM Db '!BE6 -> 0 | CZ6: ='1ST TERM Db'!BE6 -> 0 | DA6: =IF(AND(CX6=0,CY6=0,CZ6=0),0,IF(AND(CX6=0,CY6=0),CZ6/1,IF(AND(CX6=0,CZ6=0),CY6/1,IF(AND(CY6=0,CZ6=0),CX6/1,IF(CX6=0,FLOOR((CY6+CZ6)/2,0.1),IF(CY6=0,(CX6+CZ6)/2,IF(CZ6=0,(CY6+CX6)/2,FLOOR(((CX6+CY6+CZ6)/3),0.1)))))))) -> 0 | DD6: =SUM(DB6:DC6) -> 0 | DE6: ='2ND TERM Db '!BH6 -> 0 | DF6: ='1ST TERM Db'!BH6 -> 0 | DG6: =IF(AND(DD6=0,DE6=0,DF6=0),0,IF(AND(DD6=0,DE6=0),DF6/1,IF(AND(DD6=0,DF6=0),DE6/1,IF(AND(DE6=0,DF6=0),DD6/1,IF(DD6=0,FLOOR((DE6+DF6)/2,0.1),IF(DE6=0,(DD6+DF6)/2,IF(DF6=0,(DE6+DD6)/2,FLOOR(((DD6+DE6+DF6)/3),0.1)))))))) -> 0 | DJ6: =SUM(DH6:DI6) -> 0 | DK6: ='2ND TERM Db '!BK6 -> 0 | DL6: ='1ST TERM Db'!BK6 -> 0 | DM6: =IF(AND(DJ6=0,DK6=0,DL6=0),0,IF(AND(DJ6=0,DK6=0),DL6/1,IF(AND(DJ6=0,DL6=0),DK6/1,IF(AND(DK6=0,DL6=0),DJ6/1,IF(DJ6=0,FLOOR((DK6+DL6)/2,0.1),IF(DK6=0,(DJ6+DL6)/2,IF(DL6=0,(DK6+DJ6)/2,FLOOR(((DJ6+DK6+DL6)/3),0.1)))))))) -> 0 | DN6: =SUM(O6,U6,AA6,AG6,AM6,AS6,AY6,BE6,BK6,BQ6,BW6,CC6,CI6,CO6,CU6,DA6,DG6:DM6) -> 0 | DO6: =RANK(DN6,DN$4:DN$503) -> 12 | DP6: CHOOSE RATING | DQ6: CHOOSE RATING | DR6: CHOOSE RATING | DS6: CHOOSE RATING | DT6: CHOOSE RATING | DU6: CHOOSE RATING | DV6: CHOOSE RATING | DW6: CHOOSE RATING | DX6: 2025/2026 | DY6: THIRD | DZ6: CHOOSE RATING | EA6: CHOOSE RATING | EB6: CHOOSE RATING | EC6: CHOOSE RATING | ED6: CHOOSE RATING | EE6: CHOOSE RATING | EF6: CHOOSE RATING | EG6: Add the Tutor's Comment . . . | EH6: Choose Principals comment | EI6: Mr. Akinwale Ibrahim | EJ6: Next Term Begins on Monday, 14th September, 2026.
A7: 4 | B7: ='1ST TERM Db'!B7 -> ODEBUNMI OLUMIDE | C7: ='1ST TERM Db'!C7 -> 0 | D7: ='1ST TERM Db'!D7 -> MALE | E7: ='1ST TERM Db'!E7 -> SSS3C | I7: =G7-H7 -> 0 | L7: =SUM(J7:K7) -> 0 | M7: ='2ND TERM Db '!L7 -> 0 | N7: ='1ST TERM Db'!L7 -> 0 | O7: =IF(AND(L7=0,M7=0,N7=0),0,IF(AND(L7=0,M7=0),N7/1,IF(AND(L7=0,N7=0),M7/1,IF(AND(M7=0,N7=0),L7/1,IF(L7=0,FLOOR((M7+N7)/2,0.1),IF(M7=0,(L7+N7)/2,IF(N7=0,(M7+L7)/2,FLOOR(((L7+M7+N7)/3),0.1)))))))) -> 0 | R7: =SUM(P7:Q7) -> 0 | S7: ='2ND TERM Db '!O7 -> 0 | T7: ='1ST TERM Db'!O7 -> 0 | U7: =IF(AND(R7=0,S7=0,T7=0),0,IF(AND(R7=0,S7=0),T7/1,IF(AND(R7=0,T7=0),S7/1,IF(AND(S7=0,T7=0),R7/1,IF(R7=0,FLOOR((S7+T7)/2,0.1),IF(S7=0,(R7+T7)/2,IF(T7=0,(S7+R7)/2,FLOOR(((R7+S7+T7)/3),0.1)))))))) -> 0 | X7: =SUM(V7:W7) -> 0 | Y7: ='2ND TERM Db '!R7 -> 0 | Z7: ='1ST TERM Db'!R7 -> 0 | AA7: =IF(AND(X7=0,Y7=0,Z7=0),0,IF(AND(X7=0,Y7=0),Z7/1,IF(AND(X7=0,Z7=0),Y7/1,IF(AND(Y7=0,Z7=0),X7/1,IF(X7=0,FLOOR((Y7+Z7)/2,0.1),IF(Y7=0,(X7+Z7)/2,IF(Z7=0,(Y7+X7)/2,FLOOR(((X7+Y7+Z7)/3),0.1)))))))) -> 0 | AD7: =SUM(AB7:AC7) -> 0 | AE7: ='2ND TERM Db '!U7 -> 0 | AF7: ='1ST TERM Db'!U7 -> 0 | AG7: =IF(AND(AD7=0,AE7=0,AF7=0),0,IF(AND(AD7=0,AE7=0),AF7/1,IF(AND(AD7=0,AF7=0),AE7/1,IF(AND(AE7=0,AF7=0),AD7/1,IF(AD7=0,FLOOR((AE7+AF7)/2,0.1),IF(AE7=0,(AD7+AF7)/2,IF(AF7=0,(AE7+AD7)/2,FLOOR(((AD7+AE7+AF7)/3),0.1)))))))) -> 0 | AJ7: =SUM(AH7:AI7) -> 0 | AK7: ='2ND TERM Db '!X7 -> 0 | AL7: ='1ST TERM Db'!X7 -> 0 | AM7: =IF(AND(AJ7=0,AK7=0,AL7=0),0,IF(AND(AJ7=0,AK7=0),AL7/1,IF(AND(AJ7=0,AL7=0),AK7/1,IF(AND(AK7=0,AL7=0),AJ7/1,IF(AJ7=0,FLOOR((AK7+AL7)/2,0.1),IF(AK7=0,(AJ7+AL7)/2,IF(AL7=0,(AK7+AJ7)/2,FLOOR(((AJ7+AK7+AL7)/3),0.1)))))))) -> 0 | AP7: =SUM(AN7:AO7) -> 0 | AQ7: ='2ND TERM Db '!AA7 -> 0 | AR7: ='1ST TERM Db'!AA7 -> 0 | AS7: =IF(AND(AP7=0,AQ7=0,AR7=0),0,IF(AND(AP7=0,AQ7=0),AR7/1,IF(AND(AP7=0,AR7=0),AQ7/1,IF(AND(AQ7=0,AR7=0),AP7/1,IF(AP7=0,FLOOR((AQ7+AR7)/2,0.1),IF(AQ7=0,(AP7+AR7)/2,IF(AR7=0,(AQ7+AP7)/2,FLOOR(((AP7+AQ7+AR7)/3),0.1)))))))) -> 0 | AV7: =SUM(AT7:AU7) -> 0 | AW7: ='2ND TERM Db '!AD7 -> 0 | AX7: ='1ST TERM Db'!AD7 -> 0 | AY7: =IF(AND(AV7=0,AW7=0,AX7=0),0,IF(AND(AV7=0,AW7=0),AX7/1,IF(AND(AV7=0,AX7=0),AW7/1,IF(AND(AW7=0,AX7=0),AV7/1,IF(AV7=0,FLOOR((AW7+AX7)/2,0.1),IF(AW7=0,(AV7+AX7)/2,IF(AX7=0,(AW7+AV7)/2,FLOOR(((AV7+AW7+AX7)/3),0.1)))))))) -> 0 | BB7: =SUM(AZ7:BA7) -> 0 | BC7: ='2ND TERM Db '!AG7 -> 0 | BD7: ='1ST TERM Db'!AG7 -> 0 | BE7: =IF(AND(BB7=0,BC7=0,BD7=0),0,IF(AND(BB7=0,BC7=0),BD7/1,IF(AND(BB7=0,BD7=0),BC7/1,IF(AND(BC7=0,BD7=0),BB7/1,IF(BB7=0,FLOOR((BC7+BD7)/2,0.1),IF(BC7=0,(BB7+BD7)/2,IF(BD7=0,(BC7+BB7)/2,FLOOR(((BB7+BC7+BD7)/3),0.1)))))))) -> 0 | BH7: =SUM(BF7:BG7) -> 0 | BI7: ='2ND TERM Db '!AJ7 -> 0 | BJ7: ='1ST TERM Db'!AJ7 -> 19 | BK7: =IF(AND(BH7=0,BI7=0,BJ7=0),0,IF(AND(BH7=0,BI7=0),BJ7/1,IF(AND(BH7=0,BJ7=0),BI7/1,IF(AND(BI7=0,BJ7=0),BH7/1,IF(BH7=0,FLOOR((BI7+BJ7)/2,0.1),IF(BI7=0,(BH7+BJ7)/2,IF(BJ7=0,(BI7+BH7)/2,FLOOR(((BH7+BI7+BJ7)/3),0.1)))))))) -> 19 | BN7: =SUM(BL7:BM7) -> 0 | BO7: ='2ND TERM Db '!AM7 -> 0 | BP7: ='1ST TERM Db'!AM7 -> 0 | BQ7: =IF(AND(BN7=0,BO7=0,BP7=0),0,IF(AND(BN7=0,BO7=0),BP7/1,IF(AND(BN7=0,BP7=0),BO7/1,IF(AND(BO7=0,BP7=0),BN7/1,IF(BN7=0,FLOOR((BO7+BP7)/2,0.1),IF(BO7=0,(BN7+BP7)/2,IF(BP7=0,(BO7+BN7)/2,FLOOR(((BN7+BO7+BP7)/3),0.1)))))))) -> 0 | BT7: =SUM(BR7:BS7) -> 0 | BU7: ='2ND TERM Db '!AP7 -> 0 | BV7: ='1ST TERM Db'!AP7 -> 0 | BW7: =IF(AND(BT7=0,BU7=0,BV7=0),0,IF(AND(BT7=0,BU7=0),BV7/1,IF(AND(BT7=0,BV7=0),BU7/1,IF(AND(BU7=0,BV7=0),BT7/1,IF(BT7=0,FLOOR((BU7+BV7)/2,0.1),IF(BU7=0,(BT7+BV7)/2,IF(BV7=0,(BU7+BT7)/2,FLOOR(((BT7+BU7+BV7)/3),0.1)))))))) -> 0 | BZ7: =SUM(BX7:BY7) -> 0 | CA7: ='2ND TERM Db '!AS7 -> 0 | CB7: ='1ST TERM Db'!AS7 -> 0 | CC7: =IF(AND(BZ7=0,CA7=0,CB7=0),0,IF(AND(BZ7=0,CA7=0),CB7/1,IF(AND(BZ7=0,CB7=0),CA7/1,IF(AND(CA7=0,CB7=0),BZ7/1,IF(BZ7=0,FLOOR((CA7+CB7)/2,0.1),IF(CA7=0,(BZ7+CB7)/2,IF(CB7=0,(CA7+BZ7)/2,FLOOR(((BZ7+CA7+CB7)/3),0.1)))))))) -> 0 | CF7: =SUM(CD7:CE7) -> 0 | CG7: ='2ND TERM Db '!AV7 -> 0 | CH7: ='1ST TERM Db'!AV7 -> 0 | CI7: =IF(AND(CF7=0,CG7=0,CH7=0),0,IF(AND(CF7=0,CG7=0),CH7/1,IF(AND(CF7=0,CH7=0),CG7/1,IF(AND(CG7=0,CH7=0),CF7/1,IF(CF7=0,FLOOR((CG7+CH7)/2,0.1),IF(CG7=0,(CF7+CH7)/2,IF(CH7=0,(CG7+CF7)/2,FLOOR(((CF7+CG7+CH7)/3),0.1)))))))) -> 0 | CL7: =SUM(CJ7:CK7) -> 0 | CM7: ='2ND TERM Db '!AY7 -> 0 | CN7: ='1ST TERM Db'!AY7 -> 0 | CO7: =IF(AND(CL7=0,CM7=0,CN7=0),0,IF(AND(CL7=0,CM7=0),CN7/1,IF(AND(CL7=0,CN7=0),CM7/1,IF(AND(CM7=0,CN7=0),CL7/1,IF(CL7=0,FLOOR((CM7+CN7)/2,0.1),IF(CM7=0,(CL7+CN7)/2,IF(CN7=0,(CM7+CL7)/2,FLOOR(((CL7+CM7+CN7)/3),0.1)))))))) -> 0 | CR7: =SUM(CP7:CQ7) -> 0 | CS7: ='2ND TERM Db '!BB7 -> 0 | CT7: ='1ST TERM Db'!BB7 -> 0 | CU7: =IF(AND(CR7=0,CS7=0,CT7=0),0,IF(AND(CR7=0,CS7=0),CT7/1,IF(AND(CR7=0,CT7=0),CS7/1,IF(AND(CS7=0,CT7=0),CR7/1,IF(CR7=0,FLOOR((CS7+CT7)/2,0.1),IF(CS7=0,(CR7+CT7)/2,IF(CT7=0,(CS7+CR7)/2,FLOOR(((CR7+CS7+CT7)/3),0.1)))))))) -> 0 | CX7: =SUM(CV7:CW7) -> 0 | CY7: ='2ND TERM Db '!BE7 -> 0 | CZ7: ='1ST TERM Db'!BE7 -> 0 | DA7: =IF(AND(CX7=0,CY7=0,CZ7=0),0,IF(AND(CX7=0,CY7=0),CZ7/1,IF(AND(CX7=0,CZ7=0),CY7/1,IF(AND(CY7=0,CZ7=0),CX7/1,IF(CX7=0,FLOOR((CY7+CZ7)/2,0.1),IF(CY7=0,(CX7+CZ7)/2,IF(CZ7=0,(CY7+CX7)/2,FLOOR(((CX7+CY7+CZ7)/3),0.1)))))))) -> 0 | DD7: =SUM(DB7:DC7) -> 0 | DE7: ='2ND TERM Db '!BH7 -> 0 | DF7: ='1ST TERM Db'!BH7 -> 0 | DG7: =IF(AND(DD7=0,DE7=0,DF7=0),0,IF(AND(DD7=0,DE7=0),DF7/1,IF(AND(DD7=0,DF7=0),DE7/1,IF(AND(DE7=0,DF7=0),DD7/1,IF(DD7=0,FLOOR((DE7+DF7)/2,0.1),IF(DE7=0,(DD7+DF7)/2,IF(DF7=0,(DE7+DD7)/2,FLOOR(((DD7+DE7+DF7)/3),0.1)))))))) -> 0 | DJ7: =SUM(DH7:DI7) -> 0 | DK7: ='2ND TERM Db '!BK7 -> 0 | DL7: ='1ST TERM Db'!BK7 -> 0 | DM7: =IF(AND(DJ7=0,DK7=0,DL7=0),0,IF(AND(DJ7=0,DK7=0),DL7/1,IF(AND(DJ7=0,DL7=0),DK7/1,IF(AND(DK7=0,DL7=0),DJ7/1,IF(DJ7=0,FLOOR((DK7+DL7)/2,0.1),IF(DK7=0,(DJ7+DL7)/2,IF(DL7=0,(DK7+DJ7)/2,FLOOR(((DJ7+DK7+DL7)/3),0.1)))))))) -> 0 | DN7: =SUM(O7,U7,AA7,AG7,AM7,AS7,AY7,BE7,BK7,BQ7,BW7,CC7,CI7,CO7,CU7,DA7,DG7,DM7) -> 19 | DO7: =RANK(DN7,DN$4:DN$503) -> 11 | DP7: CHOOSE RATING | DQ7: CHOOSE RATING | DR7: CHOOSE RATING | DS7: CHOOSE RATING | DT7: CHOOSE RATING | DU7: CHOOSE RATING | DV7: CHOOSE RATING | DW7: CHOOSE RATING | DX7: 2025/2026 | DY7: THIRD | DZ7: CHOOSE RATING | EA7: CHOOSE RATING | EB7: CHOOSE RATING | EC7: CHOOSE RATING | ED7: CHOOSE RATING | EE7: CHOOSE RATING | EF7: CHOOSE RATING | EG7: Add the Tutor's Comment . . . | EH7: Choose Principals comment | EI7: Mr. Akinwale Ibrahim | EJ7: Next Term Begins on Monday, 14th September, 2026.
A8: 5 | B8: ='1ST TERM Db'!B8 -> SAHEED HASSAN | C8: ='1ST TERM Db'!C8 -> 0 | D8: ='1ST TERM Db'!D8 -> MALE | E8: ='1ST TERM Db'!E8 -> SSS3C | I8: =G8-H8 -> 0 | L8: =SUM(J8:K8) -> 0 | M8: ='2ND TERM Db '!L8 -> 0 | N8: ='1ST TERM Db'!L8 -> 0 | O8: =IF(AND(L8=0,M8=0,N8=0),0,IF(AND(L8=0,M8=0),N8/1,IF(AND(L8=0,N8=0),M8/1,IF(AND(M8=0,N8=0),L8/1,IF(L8=0,FLOOR((M8+N8)/2,0.1),IF(M8=0,(L8+N8)/2,IF(N8=0,(M8+L8)/2,FLOOR(((L8+M8+N8)/3),0.1)))))))) -> 0 | R8: =SUM(P8:Q8) -> 0 | S8: ='2ND TERM Db '!O8 -> 0 | T8: ='1ST TERM Db'!O8 -> 0 | U8: =IF(AND(R8=0,S8=0,T8=0),0,IF(AND(R8=0,S8=0),T8/1,IF(AND(R8=0,T8=0),S8/1,IF(AND(S8=0,T8=0),R8/1,IF(R8=0,FLOOR((S8+T8)/2,0.1),IF(S8=0,(R8+T8)/2,IF(T8=0,(S8+R8)/2,FLOOR(((R8+S8+T8)/3),0.1)))))))) -> 0 | X8: =SUM(V8:W8) -> 0 | Y8: ='2ND TERM Db '!R8 -> 0 | Z8: ='1ST TERM Db'!R8 -> 0 | AA8: =IF(AND(X8=0,Y8=0,Z8=0),0,IF(AND(X8=0,Y8=0),Z8/1,IF(AND(X8=0,Z8=0),Y8/1,IF(AND(Y8=0,Z8=0),X8/1,IF(X8=0,FLOOR((Y8+Z8)/2,0.1),IF(Y8=0,(X8+Z8)/2,IF(Z8=0,(Y8+X8)/2,FLOOR(((X8+Y8+Z8)/3),0.1)))))))) -> 0 | AD8: =SUM(AB8:AC8) -> 0 | AE8: ='2ND TERM Db '!U8 -> 0 | AF8: ='1ST TERM Db'!U8 -> 0 | AG8: =IF(AND(AD8=0,AE8=0,AF8=0),0,IF(AND(AD8=0,AE8=0),AF8/1,IF(AND(AD8=0,AF8=0),AE8/1,IF(AND(AE8=0,AF8=0),AD8/1,IF(AD8=0,FLOOR((AE8+AF8)/2,0.1),IF(AE8=0,(AD8+AF8)/2,IF(AF8=0,(AE8+AD8)/2,FLOOR(((AD8+AE8+AF8)/3),0.1)))))))) -> 0 | AJ8: =SUM(AH8:AI8) -> 0 | AK8: ='2ND TERM Db '!X8 -> 0 | AL8: ='1ST TERM Db'!X8 -> 0 | AM8: =IF(AND(AJ8=0,AK8=0,AL8=0),0,IF(AND(AJ8=0,AK8=0),AL8/1,IF(AND(AJ8=0,AL8=0),AK8/1,IF(AND(AK8=0,AL8=0),AJ8/1,IF(AJ8=0,FLOOR((AK8+AL8)/2,0.1),IF(AK8=0,(AJ8+AL8)/2,IF(AL8=0,(AK8+AJ8)/2,FLOOR(((AJ8+AK8+AL8)/3),0.1)))))))) -> 0 | AP8: =SUM(AN8:AO8) -> 0 | AQ8: ='2ND TERM Db '!AA8 -> 0 | AR8: ='1ST TERM Db'!AA8 -> 0 | AS8: =IF(AND(AP8=0,AQ8=0,AR8=0),0,IF(AND(AP8=0,AQ8=0),AR8/1,IF(AND(AP8=0,AR8=0),AQ8/1,IF(AND(AQ8=0,AR8=0),AP8/1,IF(AP8=0,FLOOR((AQ8+AR8)/2,0.1),IF(AQ8=0,(AP8+AR8)/2,IF(AR8=0,(AQ8+AP8)/2,FLOOR(((AP8+AQ8+AR8)/3),0.1)))))))) -> 0 | AV8: =SUM(AT8:AU8) -> 0 | AW8: ='2ND TERM Db '!AD8 -> 0 | AX8: ='1ST TERM Db'!AD8 -> 0 | AY8: =IF(AND(AV8=0,AW8=0,AX8=0),0,IF(AND(AV8=0,AW8=0),AX8/1,IF(AND(AV8=0,AX8=0),AW8/1,IF(AND(AW8=0,AX8=0),AV8/1,IF(AV8=0,FLOOR((AW8+AX8)/2,0.1),IF(AW8=0,(AV8+AX8)/2,IF(AX8=0,(AW8+AV8)/2,FLOOR(((AV8+AW8+AX8)/3),0.1)))))))) -> 0 | BB8: =SUM(AZ8:BA8) -> 0 | BC8: ='2ND TERM Db '!AG8 -> 0 | BD8: ='1ST TERM Db'!AG8 -> 0 | BE8: =IF(AND(BB8=0,BC8=0,BD8=0),0,IF(AND(BB8=0,BC8=0),BD8/1,IF(AND(BB8=0,BD8=0),BC8/1,IF(AND(BC8=0,BD8=0),BB8/1,IF(BB8=0,FLOOR((BC8+BD8)/2,0.1),IF(BC8=0,(BB8+BD8)/2,IF(BD8=0,(BC8+BB8)/2,FLOOR(((BB8+BC8+BD8)/3),0.1)))))))) -> 0 | BH8: =SUM(BF8:BG8) -> 0 | BI8: ='2ND TERM Db '!AJ8 -> 0 | BJ8: ='1ST TERM Db'!AJ8 -> 46 | BK8: =IF(AND(BH8=0,BI8=0,BJ8=0),0,IF(AND(BH8=0,BI8=0),BJ8/1,IF(AND(BH8=0,BJ8=0),BI8/1,IF(AND(BI8=0,BJ8=0),BH8/1,IF(BH8=0,FLOOR((BI8+BJ8)/2,0.1),IF(BI8=0,(BH8+BJ8)/2,IF(BJ8=0,(BI8+BH8)/2,FLOOR(((BH8+BI8+BJ8)/3),0.1)))))))) -> 46 | BN8: =SUM(BL8:BM8) -> 0 | BO8: ='2ND TERM Db '!AM8 -> 0 | BP8: ='1ST TERM Db'!AM8 -> 0 | BQ8: =IF(AND(BN8=0,BO8=0,BP8=0),0,IF(AND(BN8=0,BO8=0),BP8/1,IF(AND(BN8=0,BP8=0),BO8/1,IF(AND(BO8=0,BP8=0),BN8/1,IF(BN8=0,FLOOR((BO8+BP8)/2,0.1),IF(BO8=0,(BN8+BP8)/2,IF(BP8=0,(BO8+BN8)/2,FLOOR(((BN8+BO8+BP8)/3),0.1)))))))) -> 0 | BT8: =SUM(BR8:BS8) -> 0 | BU8: ='2ND TERM Db '!AP8 -> 0 | BV8: ='1ST TERM Db'!AP8 -> 0 | BW8: =IF(AND(BT8=0,BU8=0,BV8=0),0,IF(AND(BT8=0,BU8=0),BV8/1,IF(AND(BT8=0,BV8=0),BU8/1,IF(AND(BU8=0,BV8=0),BT8/1,IF(BT8=0,FLOOR((BU8+BV8)/2,0.1),IF(BU8=0,(BT8+BV8)/2,IF(BV8=0,(BU8+BT8)/2,FLOOR(((BT8+BU8+BV8)/3),0.1)))))))) -> 0 | BZ8: =SUM(BX8:BY8) -> 0 | CA8: ='2ND TERM Db '!AS8 -> 0 | CB8: ='1ST TERM Db'!AS8 -> 0 | CC8: =IF(AND(BZ8=0,CA8=0,CB8=0),0,IF(AND(BZ8=0,CA8=0),CB8/1,IF(AND(BZ8=0,CB8=0),CA8/1,IF(AND(CA8=0,CB8=0),BZ8/1,IF(BZ8=0,FLOOR((CA8+CB8)/2,0.1),IF(CA8=0,(BZ8+CB8)/2,IF(CB8=0,(CA8+BZ8)/2,FLOOR(((BZ8+CA8+CB8)/3),0.1)))))))) -> 0 | CF8: =SUM(CD8:CE8) -> 0 | CG8: ='2ND TERM Db '!AV8 -> 0 | CH8: ='1ST TERM Db'!AV8 -> 0 | CI8: =IF(AND(CF8=0,CG8=0,CH8=0),0,IF(AND(CF8=0,CG8=0),CH8/1,IF(AND(CF8=0,CH8=0),CG8/1,IF(AND(CG8=0,CH8=0),CF8/1,IF(CF8=0,FLOOR((CG8+CH8)/2,0.1),IF(CG8=0,(CF8+CH8)/2,IF(CH8=0,(CG8+CF8)/2,FLOOR(((CF8+CG8+CH8)/3),0.1)))))))) -> 0 | CL8: =SUM(CJ8:CK8) -> 0 | CM8: ='2ND TERM Db '!AY8 -> 0 | CN8: ='1ST TERM Db'!AY8 -> 0 | CO8: =IF(AND(CL8=0,CM8=0,CN8=0),0,IF(AND(CL8=0,CM8=0),CN8/1,IF(AND(CL8=0,CN8=0),CM8/1,IF(AND(CM8=0,CN8=0),CL8/1,IF(CL8=0,FLOOR((CM8+CN8)/2,0.1),IF(CM8=0,(CL8+CN8)/2,IF(CN8=0,(CM8+CL8)/2,FLOOR(((CL8+CM8+CN8)/3),0.1)))))))) -> 0 | CR8: =SUM(CP8:CQ8) -> 0 | CS8: ='2ND TERM Db '!BB8 -> 0 | CT8: ='1ST TERM Db'!BB8 -> 0 | CU8: =IF(AND(CR8=0,CS8=0,CT8=0),0,IF(AND(CR8=0,CS8=0),CT8/1,IF(AND(CR8=0,CT8=0),CS8/1,IF(AND(CS8=0,CT8=0),CR8/1,IF(CR8=0,FLOOR((CS8+CT8)/2,0.1),IF(CS8=0,(CR8+CT8)/2,IF(CT8=0,(CS8+CR8)/2,FLOOR(((CR8+CS8+CT8)/3),0.1)))))))) -> 0 | CX8: =SUM(CV8:CW8) -> 0 | CY8: ='2ND TERM Db '!BE8 -> 0 | CZ8: ='1ST TERM Db'!BE8 -> 0 | DA8: =IF(AND(CX8=0,CY8=0,CZ8=0),0,IF(AND(CX8=0,CY8=0),CZ8/1,IF(AND(CX8=0,CZ8=0),CY8/1,IF(AND(CY8=0,CZ8=0),CX8/1,IF(CX8=0,FLOOR((CY8+CZ8)/2,0.1),IF(CY8=0,(CX8+CZ8)/2,IF(CZ8=0,(CY8+CX8)/2,FLOOR(((CX8+CY8+CZ8)/3),0.1)))))))) -> 0 | DD8: =SUM(DB8:DC8) -> 0 | DE8: ='2ND TERM Db '!BH8 -> 0 | DF8: ='1ST TERM Db'!BH8 -> 0 | DG8: =IF(AND(DD8=0,DE8=0,DF8=0),0,IF(AND(DD8=0,DE8=0),DF8/1,IF(AND(DD8=0,DF8=0),DE8/1,IF(AND(DE8=0,DF8=0),DD8/1,IF(DD8=0,FLOOR((DE8+DF8)/2,0.1),IF(DE8=0,(DD8+DF8)/2,IF(DF8=0,(DE8+DD8)/2,FLOOR(((DD8+DE8+DF8)/3),0.1)))))))) -> 0 | DJ8: =SUM(DH8:DI8) -> 0 | DK8: ='2ND TERM Db '!BK8 -> 0 | DL8: ='1ST TERM Db'!BK8 -> 0 | DM8: =IF(AND(DJ8=0,DK8=0,DL8=0),0,IF(AND(DJ8=0,DK8=0),DL8/1,IF(AND(DJ8=0,DL8=0),DK8/1,IF(AND(DK8=0,DL8=0),DJ8/1,IF(DJ8=0,FLOOR((DK8+DL8)/2,0.1),IF(DK8=0,(DJ8+DL8)/2,IF(DL8=0,(DK8+DJ8)/2,FLOOR(((DJ8+DK8+DL8)/3),0.1)))))))) -> 0 | DN8: =SUM(O8,U8,AA8,AG8,AM8,AS8,AY8,BE8,BK8,BQ8,BW8,CC8,CI8,CO8,CU8,DA8,DG8:DM8) -> 46 | DO8: =RANK(DN8,DN$4:DN$503) -> 4 | DP8: CHOOSE RATING | DQ8: CHOOSE RATING | DR8: CHOOSE RATING | DS8: CHOOSE RATING | DT8: CHOOSE RATING | DU8: CHOOSE RATING | DV8: CHOOSE RATING | DW8: CHOOSE RATING | DX8: 2025/2026 | DY8: THIRD | DZ8: CHOOSE RATING | EA8: CHOOSE RATING | EB8: CHOOSE RATING | EC8: CHOOSE RATING | ED8: CHOOSE RATING | EE8: CHOOSE RATING | EF8: CHOOSE RATING | EG8: Add the Tutor's Comment . . . | EH8: Choose Principals comment | EI8: Mr. Akinwale Ibrahim | EJ8: Next Term Begins on Monday, 14th September, 2026.
